Workbook

Sheet Read Me
A1: Alex West WWTP - estimate bill of quantities
A2: Prepared 22 Oct 2026 by Claude for Mohamed. Quantity estimate from the available model and workbooks; not a priced or tender BOQ.
A4: Sources
A5: 1. 3D coordination model Alex-West-Combined-Coordination.blend (19 Oct 2026): 15,195 closed meshes for 23 structure types (34 structures incl. typical copies); element volumes, face areas, levels, pile stubs.
A6: 2. Pipe execution packages v3 (21 Oct 2026): 45 lines, lengths, sizes, fittings, crossings.
A7: 3. Pipe sequence and methodology workbook (22 Oct 2026): GWL -1.50, sheet piles, dewatering, piled slabs, flotation.
A8: Method
A9: Every model element is classified by its name and category into a BOQ class (blinding, RC base / wall / slab / column-beam / misc / plinth, mass fill, steel, grating, handrails, stairs, piles, equipment, water). Water surfaces are excluded.
A10: Concrete = closed-solid volume. Formwork = vertical faces + soffits of elevated slabs/beams/secondary elements. Reinforcement = volume x ratio. Excavation = offset prism from footprint below NG.
A11: Sheets
A12: Summary - totals per bill and key quantities; BOQ - priced bill (enter rates); Inputs - assumptions; Take-off - model data per structure and class; Structures - footprints, excavation, backfill, piles; Pipes - per-line pipe quantities; Exclusions - what is not covered.
A13: Confidence
... A16: Blue = source data; black = formula; yellow = enter / edit.

Sheet Summary
A1: Alex West WWTP - estimate BOQ summary
A2: Amounts fill in as rates are entered on the BOQ sheet. Key quantities are totals of the BOQ by code.
A4: Bill | B4: Description | C4: Amount | D4: Share
A5: 01 | B5: Grit removal and fine screens | C5: =SUMIFS(BOQ!$G$5:$G$312,BOQ!$A$5:$A$312,A5) -> 0 | D5: =IF($C$30=0,0,C5/$C$30) -> 0
A6: 02 | B6: Primary sedimentation tanks (8 basins) | C6: =SUMIFS(BOQ!$G$5:$G$312,BOQ!$A$5:$A$312,A6) -> 0 | D6: =IF($C$30=0,0,C6/$C$30) -> 0
A7: 03 | B7: Intermediate pumping station incl. shared IPS/RAS motor hall | C7: =SUMIFS(BOQ!$G$5:$G$312,BOQ!$A$5:$A$312,A7) -> 0 | D7: =IF($C$30=0,0,C7/$C$30) -> 0
A8: 04 | B8: Aeration tanks | C8: =SUMIFS(BOQ!$G$5:$G$312,BOQ!$A$5:$A$312,A8) -> 0 | D8: =IF($C$30=0,0,C8/$C$30) -> 0
A9: 05 | B9: Secondary distribution chambers A-C (3 nr) | C9: =SUMIFS(BOQ!$G$5:$G$312,BOQ!$A$5:$A$312,A9) -> 0 | D9: =IF($C$30=0,0,C9/$C$30) -> 0
A10: 06 | B10: Final sedimentation tanks A-L (12 nr) | C10: =SUMIFS(BOQ!$G$5:$G$312,BOQ!$A$5:$A$312,A10) -> 0 | D10: =IF($C$30=0,0,C10/$C$30) -> 0
A11: 07 | B11: RAS/WAS pumping station | C11: =SUMIFS(BOQ!$G$5:$G$312,BOQ!$A$5:$A$312,A11) -> 0 | D11: =IF($C$30=0,0,C11/$C$30) -> 0
A12: 08 | B12: Chlorine contact tank | C12: =SUMIFS(BOQ!$G$5:$G$312,BOQ!$A$5:$A$312,A12) -> 0 | D12: =IF($C$30=0,0,C12/$C$30) -> 0
A13: 09 | B13: Fire / service / cooling water structure | C13: =SUMIFS(BOQ!$G$5:$G$312,BOQ!$A$5:$A$312,A13) -> 0 | D13: =IF($C$30=0,0,C13/$C$30) -> 0
A14: 10 | B14: Air blower building | C14: =SUMIFS(BOQ!$G$5:$G$312,BOQ!$A$5:$A$312,A14) -> 0 | D14: =IF($C$30=0,0,C14/$C$30) -> 0
A15: 11 | B15: Primary sludge thickeners A-D (4 nr) | C15: =SUMIFS(BOQ!$G$5:$G$312,BOQ!$A$5:$A$312,A15) -> 0 | D15: =IF($C$30=0,0,C15/$C$30) -> 0
A16: 12 | B16: Anaerobic digesters 01-08 (8 nr) | C16: =SUMIFS(BOQ!$G$5:$G$312,BOQ!$A$5:$A$312,A16) -> 0 | D16: =IF($C$30=0,0,C16/$C$30) -> 0
... A29: 25 | B29: Site-wide and provisional items | C29: =SUMIFS(BOQ!$G$5:$G$312,BOQ!$A$5:$A$312,A29) -> 0 | D29: =IF($C$30=0,0,C29/$C$30) -> 0
B30: Total (excluding preliminaries, M&E, contingency) | C30: =SUM(C5:C29) -> 0
A32: Key quantities
A33: Code | B33: Quantity | C33: Unit | D33: Description
A34: RC_BASE | B34: =SUMIFS(BOQ!$E$5:$E$312,BOQ!$H$5:$H$312,A34) -> 88694.949 | C34: m3 | D34: RC rafts, bases, floors, foundations (incl. pipe slabs)
A35: RC_WALL | B35: =SUMIFS(BOQ!$E$5:$E$312,BOQ!$H$5:$H$312,A35) -> 41276.146 | C35: m3 | D35: RC walls
A36: RC_SLAB | B36: =SUMIFS(BOQ!$E$5:$E$312,BOQ!$H$5:$H$312,A36) -> 5605.6017 | C36: m3 | D36: RC suspended slabs / decks / roofs
A37: RC_COLBEAM | B37: =SUMIFS(BOQ!$E$5:$E$312,BOQ!$H$5:$H$312,A37) -> 432.11227 | C37: m3 | D37: RC columns / beams
A38: RC_MISC | B38: =SUMIFS(BOQ!$E$5:$E$312,BOQ!$H$5:$H$312,A38) -> 7944.6378 | C38: m3 | D38: RC channels, baffles, weirs, chambers
A39: RC_PLINTH | B39: =SUMIFS(BOQ!$E$5:$E$312,BOQ!$H$5:$H$312,A39) -> 1816.2575 | C39: m3 | D39: RC plinths
A40: RC_BRIDGE | B40: =SUMIFS(BOQ!$E$5:$E$312,BOQ!$H$5:$H$312,A40) -> 21.321397 | C40: m3 | D40: RC thickener bridges
A41: BLINDING | B41: =SUMIFS(BOQ!$E$5:$E$312,BOQ!$H$5:$H$312,A41) -> 6091.6547 | C41: m3 | D41: Blinding
A42: MASS_FILL | B42: =SUMIFS(BOQ!$E$5:$E$312,BOQ!$H$5:$H$312,A42) -> 590.74257 | C42: m3 | D42: Mass concrete fill
A43: FORMWORK | B43: =SUMIFS(BOQ!$E$5:$E$312,BOQ!$H$5:$H$312,A43) -> 221442.09 | C43: m2 | D43: Formwork
A44: REBAR | B44: =SUMIFS(BOQ!$E$5:$E$312,BOQ!$H$5:$H$312,A44) -> 17293.207 | C44: t | D44: Reinforcement
A45: STEEL | B45: =SUMIFS(BOQ!$E$5:$E$312,BOQ!$H$5:$H$312,A45) -> 0 | C45: t | D45: Structural steel
... A53: SITEFILL | B53: =SUMIFS(BOQ!$E$5:$E$312,BOQ!$H$5:$H$312,A53) -> 378367.47 | C53: m3 | D53: Site raising (provisional)
A54: All RC | B54: =SUM(B34:B40) -> 145791.03 | C54: m3 | D54: All reinforced concrete
A56: Cross-checks
A57: Aeration raft: model vs aeration estimate | C57: =SUMIFS('Take-off'!$E$5:$E$334,'Take-off'!$A$5:$A$334,"AER",'Take-off'!$C$5:$C$334,"RC_BASE") -> 30119.834 | D57: 30012.624 | E57: Model RC_BASE for aeration vs 30,012.6 m3 net raft (AW-AER Tracking Documentation, 18 Oct 2026)
A58: Aeration piles in model vs tracking | C58: =SUMIFS(Structures!$L$5:$L$55,Structures!$A$5:$A$55,"AER") -> 3672 | D58: 3672 | E58: 3,672 model piles; 2,079 recorded done, 19 defect, 1,568 pending (17 Oct 2026) - BOQ is gross

Sheet BOQ
A1: Alex West WWTP - estimate bill of quantities (whole project, from available information)
A2: Quantities are formulas on the Take-off, Structures and Pipes sheets. Enter rates in the yellow column (currency on Inputs). Confidence: B = structural / detailed model; C = civil-guide or provisional envelope; D = tender envelope, placeholder or allowance.
A4: Bill | B4: Item | C4: Description | D4: Unit | E4: Quantity | F4: Rate | G4: Amount | H4: Code | I4: Basis / source | J4: Confidence
A5: 01 | C5: Grit removal and fine screens
A6: 01 | B6: 01.01 | C6: Excavation below NG (-0.70) to underside of lowest element, incl. working space and side slopes; dispose / stockpile | D6: m3 | E6: =SUMIFS(Structures!$I$5:$I$55,Structures!$A$5:$A$55,"GRT") -> 1180.792 | G6: =E6*F6 -> 0 | H6: EXC | I6: Structures sheet: model footprint and lowest level; WS_STR, SLOPE_STR | J6: C
A7: 01 | B7: 01.02 | C7: Backfill around structure to NG in compacted layers | D7: m3 | E7: =SUMIFS(Structures!$J$5:$J$55,Structures!$A$5:$A$55,"GRT") -> 1002.792 | G7: =E7*F7 -> 0 | H7: BACKFILL | I7: Structures sheet | J7: C
A8: 01 | B8: 01.03 | C8: Piles 600 mm diameter (CFA / bored) - length to pile design - ALLOWANCE (no pile layout in model) | D8: no. | E8: =SUMIFS(Structures!$N$5:$N$55,Structures!$A$5:$A$55,"GRT") -> 65 | G8: =E8*F8 -> 0 | H8: PILE | I8: Footprint x PILE_DENS | J8: D
A9: 01 | B9: 01.04 | C9: Mass concrete fill / benching to sloped floors | D9: m3 | E9: =SUMIFS('Take-off'!$E$5:$E$334,'Take-off'!$A$5:$A$334,"GRT",'Take-off'!$C$5:$C$334,"MASS_FILL") -> 273.42937 | G9: =E9*F9 -> 0 | H9: MASS_FILL | I9: Model volume | J9: C
A10: 01 | B10: 01.05 | C10: Reinforced concrete rafts, bases, floors and foundations | D10: m3 | E10: =SUMIFS('Take-off'!$E$5:$E$334,'Take-off'!$A$5:$A$334,"GRT",'Take-off'!$C$5:$C$334,"RC_BASE") -> 489.22944 | G10: =E10*F10 -> 0 | H10: RC_BASE | I10: Model volume | J10: C
A11: 01 | B11: 01.06 | C11: Reinforced concrete walls and parapets | D11: m3 | E11: =SUMIFS('Take-off'!$E$5:$E$334,'Take-off'!$A$5:$A$334,"GRT",'Take-off'!$C$5:$C$334,"RC_WALL") -> 967.46983 | G11: =E11*F11 -> 0 | H11: RC_WALL | I11: Model volume | J11: C
A12: 01 | B12: 01.07 | C12: Reinforced concrete suspended slabs, decks, roofs and walkways | D12: m3 | E12: =SUMIFS('Take-off'!$E$5:$E$334,'Take-off'!$A$5:$A$334,"GRT",'Take-off'!$C$5:$C$334,"RC_SLAB") -> 224.80372 | G12: =E12*F12 -> 0 | H12: RC_SLAB | I12: Model volume | J12: C
A13: 01 | B13: 01.08 | C13: Reinforced concrete channels, baffles, weirs, chambers, hoppers and secondary elements | D13: m3 | E13: =SUMIFS('Take-off'!$E$5:$E$334,'Take-off'!$A$5:$A$334,"GRT",'Take-off'!$C$5:$C$334,"RC_MISC") -> 31.329036 | G13: =E13*F13 -> 0 | H13: RC_MISC | I13: Model volume | J13: C
A14: 01 | B14: 01.09 | C14: Formwork to vertical faces and soffits of elevated elements | D14: m2 | E14: =SUMIFS('Take-off'!$G$5:$G$334,'Take-off'!$A$5:$A$334,"GRT",'Take-off'!$C$5:$C$334,"RC_BASE")+SUMIFS('Take-off'!$G$5:$G$334,'Take-off'!$A$5:$A$334,"GRT",'Take-off'!$C$5:$C$334,"RC_WALL")+SUMIFS('Take-off'!$G$5:$G$334,'Take-off'!$A$5:$A$334,"GRT",'Take-off'!$C$5:$C$334,"RC_SLAB")+SUMIFS('Take-off'!$G$5:$G$334,'Take-off'!$A$5:$A$334,"GRT",'Take-off'!$C$5:$C$334,"RC_MISC") -> 4909.4595 | G14: =E14*F14 -> 0 | H14: FORMWORK | I14: Model face areas | J14: C
A15: 01 | B15: 01.10 | C15: High-yield steel reinforcement | D15: t | E15: =(SUMIFS('Take-off'!$E$5:$E$334,'Take-off'!$A$5:$A$334,"GRT",'Take-off'!$C$5:$C$334,"RC_BASE")*RR_BASE+SUMIFS('Take-off'!$E$5:$E$334,'Take-off'!$A$5:$A$334,"GRT",'Take-off'!$C$5:$C$334,"RC_WALL")*RR_WALL+SUMIFS('Take-off'!$E$5:$E$334,'Take-off'!$A$5:$A$334,"GRT",'Take-off'!$C$5:$C$334,"RC_SLAB")*RR_SLAB+SUMIFS('Take-off'!$E$5:$E$334,'Take-off'!$A$5:$A$334,"GRT",'Take-off'!$C$5:$C$334,"RC_MISC")*RR_MISC)/1000 -> 221.09059 | G15: =E15*F15 -> 0 | H15: REBAR | I15: Concrete volume x ratio (Inputs) | J15: D
A16: 01 | B16: 01.11 | C16: Handrails (run length) | D16: m | E16: =SUMIFS('Take-off'!$H$5:$H$334,'Take-off'!$A$5:$A$334,"GRT",'Take-off'!$C$5:$C$334,"HANDRAIL")/RAILS_PER_RUN -> 119.3 | G16: =E16*F16 -> 0 | H16: HANDRAIL | I16: Model rail members / RAILS_PER_RUN; indicative in model | J16: D
A17: 01 | B17: 01.12 | C17: Stairs, treads, landings and access steps (material to design) - modelled volume | D17: m3 | E17: =SUMIFS('Take-off'!$E$5:$E$334,'Take-off'!$A$5:$A$334,"GRT",'Take-off'!$C$5:$C$334,"STAIRS") -> 41.38145 | G17: =E17*F17 -> 0 | H17: STAIRS | I17: Model volume; 38 modelled elements | J17: D
A18: 02 | C18: Primary sedimentation tanks (8 basins)
A19: 02 | B19: 02.01 | C19: Excavation below NG (-0.70) to underside of lowest element, incl. working space and side slopes; dispose / stockpile | D19: m3 | E19: =SUMIFS(Structures!$I$5:$I$55,Structures!$A$5:$A$55,"PST") -> 56094.761 | G19: =E19*F19 -> 0 | H19: EXC | I19: Structures sheet: model footprint and lowest level; WS_STR, SLOPE_STR | J19: C
A20: 02 | B20: 02.02 | C20: Backfill around structure to NG in compacted layers | D20: m3 | E20: =SUMIFS(Structures!$J$5:$J$55,Structures!$A$5:$A$55,"PST") -> 14347.691 | G20: =E20*F20 -> 0 | H20: BACKFILL | I20: Structures sheet | J20: C
A21: 02 | B21: 02.03 | C21: Piles 600 mm diameter (CFA / bored) - length to pile design - ALLOWANCE (no pile layout in model) | D21: no. | E21: =SUMIFS(Structures!$N$5:$N$55,Structures!$A$5:$A$55,"PST") -> 646 | G21: =E21*F21 -> 0 | H21: PILE | I21: Footprint x PILE_DENS | J21: D
A22: 02 | B22: 02.04 | C22: Plain concrete blinding / screed | D22: m3 | E22: =SUMIFS('Take-off'!$E$5:$E$334,'Take-off'!$A$5:$A$334,"PST",'Take-off'!$C$5:$C$334,"BLINDING") -> 1104.2745 | G22: =E22*F22 -> 0 | H22: BLINDING | I22: Model volume | J22: C
A23: 02 | B23: 02.05 | C23: Mass concrete fill / benching to sloped floors | D23: m3 | E23: =SUMIFS('Take-off'!$E$5:$E$334,'Take-off'!$A$5:$A$334,"PST",'Take-off'!$C$5:$C$334,"MASS_FILL") -> 317.31321 | G23: =E23*F23 -> 0 | H23: MASS_FILL | I23: Model volume | J23: C
A24: 02 | B24: 02.06 | C24: Reinforced concrete rafts, bases, floors and foundations | D24: m3 | E24: =SUMIFS('Take-off'!$E$5:$E$334,'Take-off'!$A$5:$A$334,"PST",'Take-off'!$C$5:$C$334,"RC_BASE") -> 6012.3696 | G24: =E24*F24 -> 0 | H24: RC_BASE | I24: Model volume | J24: C
A25: 02 | B25: 02.07 | C25: Reinforced concrete walls and parapets | D25: m3 | E25: =SUMIFS('Take-off'!$E$5:$E$334,'Take-off'!$A$5:$A$334,"PST",'Take-off'!$C$5:$C$334,"RC_WALL") -> 2144.7301 | G25: =E25*F25 -> 0 | H25: RC_WALL | I25: Model volume | J25: C
A26: 02 | B26: 02.08 | C26: Reinforced concrete suspended slabs, decks, roofs and walkways | D26: m3 | E26: =SUMIFS('Take-off'!$E$5:$E$334,'Take-off'!$A$5:$A$334,"PST",'Take-off'!$C$5:$C$334,"RC_SLAB") -> 267.21851 | G26: =E26*F26 -> 0 | H26: RC_SLAB | I26: Model volume | J26: C
A27: 02 | B27: 02.09 | C27: Reinforced concrete columns, beams and piers | D27: m3 | E27: =SUMIFS('Take-off'!$E$5:$E$334,'Take-off'!$A$5:$A$334,"PST",'Take-off'!$C$5:$C$334,"RC_COLBEAM") -> 47.606454 | G27: =E27*F27 -> 0 | H27: RC_COLBEAM | I27: Model volume | J27: C
A28: 02 | B28: 02.10 | C28: Reinforced concrete channels, baffles, weirs, chambers, hoppers and secondary elements | D28: m3 | E28: =SUMIFS('Take-off'!$E$5:$E$334,'Take-off'!$A$5:$A$334,"PST",'Take-off'!$C$5:$C$334,"RC_MISC") -> 356.30565 | G28: =E28*F28 -> 0 | H28: RC_MISC | I28: Model volume | J28: C
A29: 02 | B29: 02.11 | C29: Formwork to vertical faces and soffits of elevated elements | D29: m2 | E29: =SUMIFS('Take-off'!$G$5:$G$334,'Take-off'!$A$5:$A$334,"PST",'Take-off'!$C$5:$C$334,"RC_BASE")+SUMIFS('Take-off'!$G$5:$G$334,'Take-off'!$A$5:$A$334,"PST",'Take-off'!$C$5:$C$334,"RC_WALL")+SUMIFS('Take-off'!$G$5:$G$334,'Take-off'!$A$5:$A$334,"PST",'Take-off'!$C$5:$C$334,"RC_SLAB")+SUMIFS('Take-off'!$G$5:$G$334,'Take-off'!$A$5:$A$334,"PST",'Take-off'!$C$5:$C$334,"RC_COLBEAM")+SUMIFS('Take-off'!$G$5:$G$334,'Take-off'!$A$5:$A$334,"PST",'Take-off'!$C$5:$C$334,"RC_MISC") -> 15309.27 | G29: =E29*F29 -> 0 | H29: FORMWORK | I29: Model face areas | J29: C
A30: 02 | B30: 02.12 | C30: High-yield steel reinforcement | D30: t | E30: =(SUMIFS('Take-off'!$E$5:$E$334,'Take-off'!$A$5:$A$334,"PST",'Take-off'!$C$5:$C$334,"RC_BASE")*RR_BASE+SUMIFS('Take-off'!$E$5:$E$334,'Take-off'!$A$5:$A$334,"PST",'Take-off'!$C$5:$C$334,"RC_WALL")*RR_WALL+SUMIFS('Take-off'!$E$5:$E$334,'Take-off'!$A$5:$A$334,"PST",'Take-off'!$C$5:$C$334,"RC_SLAB")*RR_SLAB+SUMIFS('Take-off'!$E$5:$E$334,'Take-off'!$A$5:$A$334,"PST",'Take-off'!$C$5:$C$334,"RC_COLBEAM")*RR_COLBEAM+SUMIFS('Take-off'!$E$5:$E$334,'Take-off'!$A$5:$A$334,"PST",'Take-off'!$C$5:$C$334,"RC_MISC")*RR_MISC)/1000 -> 1033.2131 | G30: =E30*F30 -> 0 | H30: REBAR | I30: Concrete volume x ratio (Inputs) | J30: D
A31: 02 | B31: 02.13 | C31: Handrails (run length) | D31: m | E31: =SUMIFS('Take-off'!$H$5:$H$334,'Take-off'!$A$5:$A$334,"PST",'Take-off'!$C$5:$C$334,"HANDRAIL")/RAILS_PER_RUN -> 1121.6 | G31: =E31*F31 -> 0 | H31: HANDRAIL | I31: Model rail members / RAILS_PER_RUN; indicative in model | J31: D
A32: 02 | B32: 02.14 | C32: Stairs, treads, landings and access steps (material to design) - modelled volume | D32: m3 | E32: =SUMIFS('Take-off'!$E$5:$E$334,'Take-off'!$A$5:$A$334,"PST",'Take-off'!$C$5:$C$334,"STAIRS") -> 64.04695 | G32: =E32*F32 -> 0 | H32: STAIRS | I32: Model volume; 90 modelled elements | J32: D
A33: 03 | C33: Intermediate pumping station incl. shared IPS/RAS motor hall
A34: 03 | B34: 03.01 | C34: Excavation below NG (-0.70) to underside of lowest element, incl. working space and side slopes; dispose / stockpile | D34: m3 | E34: =SUMIFS(Structures!$I$5:$I$55,Structures!$A$5:$A$55,"IPS") -> 11780.046 | G34: =E34*F34 -> 0 | H34: EXC | I34: Structures sheet: model footprint and lowest level; WS_STR, SLOPE_STR | J34: C
A35: 03 | B35: 03.02 | C35: Backfill around structure to NG in compacted layers | D35: m3 | E35: =SUMIFS(Structures!$J$5:$J$55,Structures!$A$5:$A$55,"IPS") -> 5966.7957 | G35: =E35*F35 -> 0 | H35: BACKFILL | I35: Structures sheet | J35: C
A36: 03 | B36: 03.03 | C36: Piles 600 mm diameter (CFA / bored) - length to pile design - ALLOWANCE (no pile layout in model) | D36: no. | E36: =SUMIFS(Structures!$N$5:$N$55,Structures!$A$5:$A$55,"IPS") -> 118 | G36: =E36*F36 -> 0 | H36: PILE | I36: Footprint x PILE_DENS | J36: D
A37: 03 | B37: 03.04 | C37: Reinforced concrete rafts, bases, floors and foundations | D37: m3 | E37: =SUMIFS('Take-off'!$E$5:$E$334,'Take-off'!$A$5:$A$334,"IPS",'Take-off'!$C$5:$C$334,"RC_BASE") -> 776.28286 | G37: =E37*F37 -> 0 | H37: RC_BASE | I37: Model volume | J37: C
A38: 03 | B38: 03.05 | C38: Reinforced concrete walls and parapets | D38: m3 | E38: =SUMIFS('Take-off'!$E$5:$E$334,'Take-off'!$A$5:$A$334,"IPS",'Take-off'!$C$5:$C$334,"RC_WALL") -> 1428.0989 | G38: =E38*F38 -> 0 | H38: RC_WALL | I38: Model volume | J38: C
A39: 03 | B39: 03.06 | C39: Reinforced concrete suspended slabs, decks, roofs and walkways | D39: m3 | E39: =SUMIFS('Take-off'!$E$5:$E$334,'Take-off'!$A$5:$A$334,"IPS",'Take-off'!$C$5:$C$334,"RC_SLAB") -> 371.40035 | G39: =E39*F39 -> 0 | H39: RC_SLAB | I39: Model volume | J39: C
A40: 03 | B40: 03.07 | C40: Reinforced concrete channels, baffles, weirs, chambers, hoppers and secondary elements | D40: m3 | E40: =SUMIFS('Take-off'!$E$5:$E$334,'Take-off'!$A$5:$A$334,"IPS",'Take-off'!$C$5:$C$334,"RC_MISC") -> 223.0756 | G40: =E40*F40 -> 0 | H40: RC_MISC | I40: Model volume | J40: C
A41: 03 | B41: 03.08 | C41: Formwork to vertical faces and soffits of elevated elements | D41: m2 | E41: =SUMIFS('Take-off'!$G$5:$G$334,'Take-off'!$A$5:$A$334,"IPS",'Take-off'!$C$5:$C$334,"RC_BASE")+SUMIFS('Take-off'!$G$5:$G$334,'Take-off'!$A$5:$A$334,"IPS",'Take-off'!$C$5:$C$334,"RC_WALL")+SUMIFS('Take-off'!$G$5:$G$334,'Take-off'!$A$5:$A$334,"IPS",'Take-off'!$C$5:$C$334,"RC_SLAB")+SUMIFS('Take-off'!$G$5:$G$334,'Take-off'!$A$5:$A$334,"IPS",'Take-off'!$C$5:$C$334,"RC_MISC") -> 6403.9658 | G41: =E41*F41 -> 0 | H41: FORMWORK | I41: Model face areas | J41: C
...

Sheet Inputs
A1: Inputs and assumptions
A2: Yellow = edit. Quantities in the BOQ recalculate from these values. Rates are entered on the BOQ sheet.
A4: Name | B4: Description | C4: Value | D4: Unit | E4: Source / status
A5: General
A6: CURRENCY | B6: Currency of rates | C6: EGP | E6: Enter rates in this currency on the BOQ sheet.
A7: NG | B7: Adopted natural ground level | C7: -0.7 | D7: m | E7: Package workbook D-004 (Mohamed, 20 Oct 2026).
A8: FL | B8: Finished ground level | C8: 1 | D8: m | E8: Package workbook D-004.
A9: Earthworks to structures
A10: WS_STR | B10: Working space around structure footprint at formation | C10: 1 | D10: m | E10: Same as agreed for pipes (21 Oct 2026).
A11: SLOPE_STR | B11: Excavation side slope (H per 1 V); 0 = vertical (shored) | C11: 1.5 | D11: H:V | E11: ASSUMPTION - soft silty clay. Temporary works design governs.
A12: Piling
A13: PILE_DENS | B13: Allowance where the model has no piles: Ø600 piles per m2 of footprint | C13: 0.1 | D13: no./m2 | E13: Calibrated to aeration: 3,672 modelled piles / 34,995 m2 footprint = 0.105. ALLOWANCE only.
A14: Reinforcement ratios (kg per m3 of concrete) - ASSUMPTIONS unless noted
A15: RR_BASE | B15: Rafts, bases and foundations | C15: 107 | D15: kg/m3 | E15: Aeration raft estimate 3,203 t / 30,012 m3 (model text "AW-AER Tracking Documentation", incl. 10% laps and 10% extra bars).
A16: RR_WALL | B16: Walls and parapets | C16: 140 | D16: kg/m3 | E16: ASSUMPTION - water-retaining walls.
A17: RR_SLAB | B17: Suspended slabs, decks, roofs, walkways | C17: 130 | D17: kg/m3 | E17: ASSUMPTION.
A18: RR_COLBEAM | B18: Columns, beams, piers | C18: 180 | D18: kg/m3 | E18: ASSUMPTION.
A19: RR_MISC | B19: Channels, baffles, weirs, chambers, hoppers | C19: 130 | D19: kg/m3 | E19: ASSUMPTION.
A20: RR_PLINTH | B20: Equipment plinths and pads | C20: 80 | D20: kg/m3 | E20: ASSUMPTION.
A21: RR_BRIDGE | B21: Concrete bridge members (thickeners) | C21: 200 | D21: kg/m3 | E21: ASSUMPTION - slender bridge members. Bridge is concrete (Mohamed, 22 Oct 2026); model collection is labelled "Steel truss".
A22: RR_PIPESLAB | B22: Piled slab under pipes | C22: 110 | D22: kg/m3 | E22: ASSUMPTION - no slab design.
A23: Steel and metalwork
A24: STEEL_DENS | B24: Density of steel | C24: 7.85 | D24: t/m3 | E24: Physical constant; applied to modelled steel member volume.
A25: RAILS_PER_RUN | B25: Rail members per handrail run (top + knee rail) | C25: 2 | D25: no. | E25: ASSUMPTION - modelled rails are individual members.
A26: Underground pipework
A27: WS_PIPE | B27: Working space each side of pipe (trench bottom width = OD + 2 x WS) | C27: 1 | D27: m | E27: AGREED 21 Oct 2026.
A28: SURR_ABOVE | B28: Granular surround above pipe crown | C28: 0.3 | D28: m | E28: ASSUMPTION.
A29: Site-wide provisional
A30: SITE_AREA | B30: Developed area for site raising (convex hull of all modelled assets) | C30: 312422 | D30: m2 | E30: Computed from the 3D model; site boundary not in the model - replace with surveyed area.
A31: SITE_DEDUCT | B31: Deduct footprint of structures from site raising (1 = yes) | C31: 1 | D31: -

Sheet Take-off
A1: Take-off from the 3D coordination model (Alex-West-Combined-Coordination.blend, 19 Oct 2026)
A2: One row per structure / element class. Volumes and areas are measured on closed model solids (all 15,195 meshes are closed). Formwork = vertical faces + soffits of elevated elements. Blue = model data; the BOQ sums these rows.
A4: Bill | B4: Asset | C4: Element class | D4: Elements (no.) | E4: Volume (m3) | F4: Top area (m2) | G4: Formwork area (m2) | H4: Rail member length (m) | I4: Lowest level (m) | J4: Element names (sample)
A5: GRT | B5: AW-GRT | C5: HANDRAIL | D5: 71 | E5: 0.48918001 | F5: 0.11365928 | G5: 0 | H5: 238.6 | I5: 6.3000002 | J5: Perimeter post; Perimeter rail; Raised walkway handrail; Raised walkway post
A6: GRT | B6: AW-GRT | C6: MASS_FILL | D6: 32 | E6: 273.42937 | F6: 150.65718 | G6: 0 | H6: 0 | I6: 0.5 | J6: G1 floor slope 1-; G1 floor slope 2-; G2 floor slope 1-; G2 floor slope 2-; G3 floor slope 1-; G3 floor slope 2-
A7: GRT | B7: AW-GRT | C7: RC_BASE | D7: 7 | E7: 489.22944 | F7: 647.31583 | G7: 192.32061 | H7: 0 | I7: -5.6999998 | J7: Deep outlet well base; Grit common raft; Pair 1 inlet distributor floor; Pair 2 inlet distributor floor; Rejected bypass floor envelope; Screen common floor
A8: GRT | B8: AW-GRT | C8: RC_MISC | D8: 58 | E8: 31.329036 | F8: 28.726102 | G8: 448.80041 | H8: 0 | I8: -5.1999998 | J8: Deep outlet well west below screen; G1 GRP stilling baffle; G1 inlet distributor cheek; G1 scum trough bottom; G1 scum trough side; G2 GRP stilling baffle
A9: GRT | B9: AW-GRT | C9: RC_SLAB | D9: 21 | E9: 224.80372 | F9: 511.13832 | G9: 736.25011 | H9: 0 | I9: 2.5 | J9: Deep outlet well access deck; Flume internal walkway; G1 lane walkway; G2 lane walkway; G3 lane walkway; G4 lane walkway
A10: GRT | B10: AW-GRT | C10: RC_WALL | D10: 42 | E10: 967.46983 | F10: 298.56257 | G10: 3532.0884 | H10: 0 | I10: -5.1999998 | J10: Deep outlet well east wall; Deep outlet well north wall; Deep outlet well south wall; Drawn flume wall -4.45; Drawn flume wall -6.45; Full dividing wall
A11: GRT | B11: AW-GRT | C11: STAIRS | D11: 38 | E11: 41.38145 | F11: 10.259949 | G11: 0 | H11: 0 | I11: -1.37 | J11: Southwest stair tread
A12: PST | B12: AW-PST | C12: BLINDING | D12: 17 | E12: 1104.2745 | F12: 5587.3875 | G12: 0 | H12: 0 | I12: -2.2 | J12: Basin 01 hopper transverse screed; Basin 02 hopper transverse screed; Basin 03 hopper transverse screed; Basin 04 hopper transverse screed; Basin 05 hopper transverse screed; Basin 06 hopper transverse screed
A13: PST | B13: AW-PST | C13: HANDRAIL | D13: 576 | E13: 4.5462477 | F13: 0.9214278 | G13: 0 | H13: 2243.2 | I13: 4 | J13: Basin 01 walkway rail; Basin 01 walkway rail post; Basin 02 walkway rail; Basin 02 walkway rail post; Basin 03 walkway rail; Basin 03 walkway rail post
A14: PST | B14: AW-PST | C14: MASS_FILL | D14: 8 | E14: 317.31321 | F14: 403.36644 | G14: 0 | H14: 0 | I14: -0.93000001 | J14: Basin 01 outlet-zone sloping fill; Basin 02 outlet-zone sloping fill; Basin 03 outlet-zone sloping fill; Basin 04 outlet-zone sloping fill; Basin 05 outlet-zone sloping fill; Basin 06 outlet-zone sloping fill
A15: PST | B15: AW-PST | C15: RC_BASE | D15: 86 | E15: 6012.3696 | F15: 6454.3794 | G15: 971.77277 | H15: 0 | I15: -7.6000004 | J15: Basin 01 outlet finger base; Basin 01 sloping hopper slab; Basin 01 sludge trough base; Basin 02 outlet finger base; Basin 02 sloping hopper slab; Basin 02 sludge trough base
A16: PST | B16: AW-PST | C16: RC_COLBEAM | D16: 88 | E16: 47.606454 | F16: 20.880032 | G16: 392.15996 | H16: 0 | I16: -0.62999958 | J16: Basin 01 baffle pier; Basin 02 baffle pier; Basin 03 baffle pier; Basin 04 baffle pier; Basin 05 baffle pier; Basin 06 baffle pier
... A334: ABPH | B334: AW-ABPH | C334: RC_WALL | D334: 9 | E334: 73.827568 | F334: 21.920426 | G334: 534.28388 | H334: 0 | I334: 0.69999999 | J334: East end wall; East parapet; Front parapet; Front wall; Rear parapet; Rear wall

Sheet Structures
A1: Structures - footprint, excavation, backfill and piles
A2: Footprint = plan convex hull of elements that go below NG. Excavation from NG to the lowest element with working space and side slope (volume of an offset prism). Backfill = excavation - footprint x depth. Piles: modelled count where the model has piles, otherwise an allowance.
A4: Bill | B4: Asset | C4: Structure | D4: Model stage (manifest 19 Oct 2026) | E4: Footprint below NG (m2) | F4: Footprint perimeter (m) | G4: Lowest level (m) | H4: Depth below NG (m) | I4: Excavation (m3) | J4: Backfill (m3) | K4: Base top area (m2) | L4: Piles in model (no.) | M4: Pile basis | N4: Piles for BOQ (no.)
A5: GRT | B5: AW-GRT | C5: Grit removal and fine screens | D5: Civil Guide Rev01 coordination reconstruction | E5: 35.6 | F5: 24.2 | G5: -5.7 | H5: =IF(E5=0,0,MAX(0,NG-G5)) -> 5 | I5: =H5*E5+F5*(WS_STR*H5+SLOPE_STR*H5^2/2)+PI()*(WS_STR^2*H5+WS_STR*SLOPE_STR*H5^2+SLOPE_STR^2*H5^3/3) -> 1180.792 | J5: =MAX(0,I5-E5*H5) -> 1002.792 | K5: 647.3 | L5: 0 | M5: Allowance: footprint x PILE_DENS | N5: =ROUNDUP(MAX(E5,K5)*PILE_DENS,0) -> 65
A6: PST | B6: AW-PST | C6: Primary sedimentation package | D6: Eight new basins CGD Rev01 | E6: 6050.3 | F6: 312.8 | G6: -7.6 | H6: =IF(E6=0,0,MAX(0,NG-G6)) -> 6.9 | I6: =H6*E6+F6*(WS_STR*H6+SLOPE_STR*H6^2/2)+PI()*(WS_STR^2*H6+WS_STR*SLOPE_STR*H6^2+SLOPE_STR^2*H6^3/3) -> 56094.761 | J6: =MAX(0,I6-E6*H6) -> 14347.691 | K6: 6454.4 | L6: 0 | M6: Allowance: footprint x PILE_DENS | N6: =ROUNDUP(MAX(E6,K6)*PILE_DENS,0) -> 646
A7: IPS | B7: AW-IPS | C7: Intermediate pumping station | D7: CGD Rev01 civil envelope | E7: 842.5 | F7: 116.1 | G7: -7.6 | H7: =IF(E7=0,0,MAX(0,NG-G7)) -> 6.9 | I7: =H7*E7+F7*(WS_STR*H7+SLOPE_STR*H7^2/2)+PI()*(WS_STR^2*H7+WS_STR*SLOPE_STR*H7^2+SLOPE_STR^2*H7^3/3) -> 11780.046 | J7: =MAX(0,I7-E7*H7) -> 5966.7957 | K7: 801.5 | L7: 0 | M7: Allowance: footprint x PILE_DENS | N7: =ROUNDUP(MAX(E7,K7)*PILE_DENS,0) -> 85
A8: IPS | B8: AW-IPS-SHARED | C8: Shared IPS / RAS motor hall and distribution channel | D8: CGD Rev01 envelope; once only | E8: 0 | F8: 0 | G8: 3.5 | H8: =IF(E8=0,0,MAX(0,NG-G8)) -> 0 | I8: =H8*E8+F8*(WS_STR*H8+SLOPE_STR*H8^2/2)+PI()*(WS_STR^2*H8+WS_STR*SLOPE_STR*H8^2+SLOPE_STR^2*H8^3/3) -> 0 | J8: =MAX(0,I8-E8*H8) -> 0 | K8: 321.6 | L8: 0 | M8: Allowance: footprint x PILE_DENS | N8: =ROUNDUP(MAX(E8,K8)*PILE_DENS,0) -> 33
A9: AER | B9: AW-AER | C9: Aeration tank complex | D9: Structural reconstruction | E9: 34994.8 | F9: 774.3 | G9: -3.1 | H9: =IF(E9=0,0,MAX(0,NG-G9)) -> 2.4 | I9: =H9*E9+F9*(WS_STR*H9+SLOPE_STR*H9^2/2)+PI()*(WS_STR^2*H9+WS_STR*SLOPE_STR*H9^2+SLOPE_STR^2*H9^3/3) -> 89258.071 | J9: =MAX(0,I9-E9*H9) -> 5270.5512 | K9: 33611.3 | L9: 3672 | M9: Model (display stubs) | N9: =L9 -> 3672
A10: SDC | B10: AW-SDC-A | C10: Secondary distribution chamber A | D10: CGD Rev02 envelope | E10: 96.8 | F10: 34.9 | G10: -5.7 | H10: =IF(E10=0,0,MAX(0,NG-G10)) -> 5 | I10: =H10*E10+F10*(WS_STR*H10+SLOPE_STR*H10^2/2)+PI()*(WS_STR^2*H10+WS_STR*SLOPE_STR*H10^2+SLOPE_STR^2*H10^3/3) -> 1740.917 | J10: =MAX(0,I10-E10*H10) -> 1256.917 | K10: 230 | L10: 0 | M10: Allowance: footprint x PILE_DENS | N10: =ROUNDUP(MAX(E10,K10)*PILE_DENS,0) -> 23
A11: SDC | B11: AW-SDC-B | C11: Secondary distribution chamber B | D11: CGD Rev02 envelope | E11: 96.8 | F11: 34.9 | G11: -5.7 | H11: =IF(E11=0,0,MAX(0,NG-G11)) -> 5 | I11: =H11*E11+F11*(WS_STR*H11+SLOPE_STR*H11^2/2)+PI()*(WS_STR^2*H11+WS_STR*SLOPE_STR*H11^2+SLOPE_STR^2*H11^3/3) -> 1740.917 | J11: =MAX(0,I11-E11*H11) -> 1256.917 | K11: 230 | L11: 0 | M11: Allowance: footprint x PILE_DENS | N11: =ROUNDUP(MAX(E11,K11)*PILE_DENS,0) -> 23
A12: SDC | B12: AW-SDC-C | C12: Secondary distribution chamber C | D12: CGD Rev02 envelope | E12: 96.8 | F12: 34.9 | G12: -5.7 | H12: =IF(E12=0,0,MAX(0,NG-G12)) -> 5 | I12: =H12*E12+F12*(WS_STR*H12+SLOPE_STR*H12^2/2)+PI()*(WS_STR^2*H12+WS_STR*SLOPE_STR*H12^2+SLOPE_STR^2*H12^3/3) -> 1740.917 | J12: =MAX(0,I12-E12*H12) -> 1256.917 | K12: 230 | L12: 0 | M12: Allowance: footprint x PILE_DENS | N12: =ROUNDUP(MAX(E12,K12)*PILE_DENS,0) -> 23
A13: FST | B13: AW-FST-A | C13: Final sedimentation tank A | D13: Typical structural instance | E13: 2550.4 | F13: 179 | G13: -4.5 | H13: =IF(E13=0,0,MAX(0,NG-G13)) -> 3.8 | I13: =H13*E13+F13*(WS_STR*H13+SLOPE_STR*H13^2/2)+PI()*(WS_STR^2*H13+WS_STR*SLOPE_STR*H13^2+SLOPE_STR^2*H13^3/3) -> 12519.564 | J13: =MAX(0,I13-E13*H13) -> 2828.0441 | K13: 2668.1 | L13: 213 | M13: Model (display stubs; FST stubs are placeholders) | N13: =L13 -> 213
A14: FST | B14: AW-FST-B | C14: Final sedimentation tank B | D14: Typical structural instance | E14: 2550.2 | F14: 179 | G14: -4.5 | H14: =IF(E14=0,0,MAX(0,NG-G14)) -> 3.8 | I14: =H14*E14+F14*(WS_STR*H14+SLOPE_STR*H14^2/2)+PI()*(WS_STR^2*H14+WS_STR*SLOPE_STR*H14^2+SLOPE_STR^2*H14^3/3) -> 12518.804 | J14: =MAX(0,I14-E14*H14) -> 2828.0441 | K14: 2668.1 | L14: 213 | M14: Model (display stubs; FST stubs are placeholders) | N14: =L14 -> 213
A15: FST | B15: AW-FST-C | C15: Final sedimentation tank C | D15: Typical structural instance | E15: 2550.3 | F15: 179 | G15: -4.5 | H15: =IF(E15=0,0,MAX(0,NG-G15)) -> 3.8 | I15: =H15*E15+F15*(WS_STR*H15+SLOPE_STR*H15^2/2)+PI()*(WS_STR^2*H15+WS_STR*SLOPE_STR*H15^2+SLOPE_STR^2*H15^3/3) -> 12519.184 | J15: =MAX(0,I15-E15*H15) -> 2828.0441 | K15: 2668.1 | L15: 213 | M15: Model (display stubs; FST stubs are placeholders) | N15: =L15 -> 213
A16: FST | B16: AW-FST-D | C16: Final sedimentation tank D | D16: Typical structural instance | E16: 2550.3 | F16: 179 | G16: -4.5 | H16: =IF(E16=0,0,MAX(0,NG-G16)) -> 3.8 | I16: =H16*E16+F16*(WS_STR*H16+SLOPE_STR*H16^2/2)+PI()*(WS_STR^2*H16+WS_STR*SLOPE_STR*H16^2+SLOPE_STR^2*H16^3/3) -> 12519.184 | J16: =MAX(0,I16-E16*H16) -> 2828.0441 | K16: 2668.1 | L16: 213 | M16: Model (display stubs; FST stubs are placeholders) | N16: =L16 -> 213
A17: FST | B17: AW-FST-E | C17: Final sedimentation tank E | D17: Typical structural instance | E17: 2550.2 | F17: 179 | G17: -4.5 | H17: =IF(E17=0,0,MAX(0,NG-G17)) -> 3.8 | I17: =H17*E17+F17*(WS_STR*H17+SLOPE_STR*H17^2/2)+PI()*(WS_STR^2*H17+WS_STR*SLOPE_STR*H17^2+SLOPE_STR^2*H17^3/3) -> 12518.804 | J17: =MAX(0,I17-E17*H17) -> 2828.0441 | K17: 2668.1 | L17: 213 | M17: Model (display stubs; FST stubs are placeholders) | N17: =L17 -> 213
A18: FST | B18: AW-FST-F | C18: Final sedimentation tank F | D18: Typical structural instance | E18: 2550.3 | F18: 179 | G18: -4.5 | H18: =IF(E18=0,0,MAX(0,NG-G18)) -> 3.8 | I18: =H18*E18+F18*(WS_STR*H18+SLOPE_STR*H18^2/2)+PI()*(WS_STR^2*H18+WS_STR*SLOPE_STR*H18^2+SLOPE_STR^2*H18^3/3) -> 12519.184 | J18: =MAX(0,I18-E18*H18) -> 2828.0441 | K18: 2668.1 | L18: 213 | M18: Model (display stubs; FST stubs are placeholders) | N18: =L18 -> 213
A19: FST | B19: AW-FST-G | C19: Final sedimentation tank G | D19: Typical structural instance | E19: 2550.3 | F19: 179 | G19: -4.5 | H19: =IF(E19=0,0,MAX(0,NG-G19)) -> 3.8 | I19: =H19*E19+F19*(WS_STR*H19+SLOPE_STR*H19^2/2)+PI()*(WS_STR^2*H19+WS_STR*SLOPE_STR*H19^2+SLOPE_STR^2*H19^3/3) -> 12519.184 | J19: =MAX(0,I19-E19*H19) -> 2828.0441 | K19: 2668.1 | L19: 213 | M19: Model (display stubs; FST stubs are placeholders) | N19: =L19 -> 213
A20: FST | B20: AW-FST-H | C20: Final sedimentation tank H | D20: Typical structural instance | E20: 2550.3 | F20: 179 | G20: -4.5 | H20: =IF(E20=0,0,MAX(0,NG-G20)) -> 3.8 | I20: =H20*E20+F20*(WS_STR*H20+SLOPE_STR*H20^2/2)+PI()*(WS_STR^2*H20+WS_STR*SLOPE_STR*H20^2+SLOPE_STR^2*H20^3/3) -> 12519.184 | J20: =MAX(0,I20-E20*H20) -> 2828.0441 | K20: 2668.1 | L20: 213 | M20: Model (display stubs; FST stubs are placeholders) | N20: =L20 -> 213
A21: FST | B21: AW-FST-I | C21: Final sedimentation tank I | D21: Typical structural instance | E21: 2550.4 | F21: 179 | G21: -4.5 | H21: =IF(E21=0,0,MAX(0,NG-G21)) -> 3.8 | I21: =H21*E21+F21*(WS_STR*H21+SLOPE_STR*H21^2/2)+PI()*(WS_STR^2*H21+WS_STR*SLOPE_STR*H21^2+SLOPE_STR^2*H21^3/3) -> 12519.564 | J21: =MAX(0,I21-E21*H21) -> 2828.0441 | K21: 2668.1 | L21: 213 | M21: Model (display stubs; FST stubs are placeholders) | N21: =L21 -> 213
A22: FST | B22: AW-FST-J | C22: Final sedimentation tank J | D22: Typical structural instance | E22: 2550.2 | F22: 179 | G22: -4.5 | H22: =IF(E22=0,0,MAX(0,NG-G22)) -> 3.8 | I22: =H22*E22+F22*(WS_STR*H22+SLOPE_STR*H22^2/2)+PI()*(WS_STR^2*H22+WS_STR*SLOPE_STR*H22^2+SLOPE_STR^2*H22^3/3) -> 12518.804 | J22: =MAX(0,I22-E22*H22) -> 2828.0441 | K22: 2668.1 | L22: 213 | M22: Model (display stubs; FST stubs are placeholders) | N22: =L22 -> 213
A23: FST | B23: AW-FST-K | C23: Final sedimentation tank K | D23: Typical structural instance | E23: 2550.3 | F23: 179 | G23: -4.5 | H23: =IF(E23=0,0,MAX(0,NG-G23)) -> 3.8 | I23: =H23*E23+F23*(WS_STR*H23+SLOPE_STR*H23^2/2)+PI()*(WS_STR^2*H23+WS_STR*SLOPE_STR*H23^2+SLOPE_STR^2*H23^3/3) -> 12519.184 | J23: =MAX(0,I23-E23*H23) -> 2828.0441 | K23: 2668.1 | L23: 213 | M23: Model (display stubs; FST stubs are placeholders) | N23: =L23 -> 213
A24: FST | B24: AW-FST-L | C24: Final sedimentation tank L | D24: Typical structural instance | E24: 2550.3 | F24: 179 | G24: -4.5 | H24: =IF(E24=0,0,MAX(0,NG-G24)) -> 3.8 | I24: =H24*E24+F24*(WS_STR*H24+SLOPE_STR*H24^2/2)+PI()*(WS_STR^2*H24+WS_STR*SLOPE_STR*H24^2+SLOPE_STR^2*H24^3/3) -> 12519.184 | J24: =MAX(0,I24-E24*H24) -> 2828.0441 | K24: 2668.1 | L24: 213 | M24: Model (display stubs; FST stubs are placeholders) | N24: =L24 -> 213
A25: RAS | B25: AW-RASWAS | C25: RAS/WAS pumping station | D25: CGD Rev01 civil envelope | E25: 163.1 | F25: 59.3 | G25: -9 | H25: =IF(E25=0,0,MAX(0,NG-G25)) -> 8.3 | I25: =H25*E25+F25*(WS_STR*H25+SLOPE_STR*H25^2/2)+PI()*(WS_STR^2*H25+WS_STR*SLOPE_STR*H25^2+SLOPE_STR^2*H25^3/3) -> 6607.7558 | J25: =MAX(0,I25-E25*H25) -> 5254.0258 | K25: 525.8 | L25: 0 | M25: Allowance: footprint x PILE_DENS | N25: =ROUNDUP(MAX(E25,K25)*PILE_DENS,0) -> 53
A26: CCT | B26: AW-CCT | C26: Chlorine contact tank | D26: Civil Guide Rev01 coordination reconstruction | E26: 3811.7 | F26: 263.9 | G26: -6.6 | H26: =IF(E26=0,0,MAX(0,NG-G26)) -> 5.9 | I26: =H26*E26+F26*(WS_STR*H26+SLOPE_STR*H26^2/2)+PI()*(WS_STR^2*H26+WS_STR*SLOPE_STR*H26^2+SLOPE_STR^2*H26^3/3) -> 31602.296 | J26: =MAX(0,I26-E26*H26) -> 9113.2658 | K26: 6762.2 | L26: 0 | M26: Allowance: footprint x PILE_DENS | N26: =ROUNDUP(MAX(E26,K26)*PILE_DENS,0) -> 677
A27: FIRE | B27: AW-FIRE | C27: Fire / services / cooling | D27: Civil Guide Rev00 coordination reconstruction | E27: 689.1 | F27: 103.7 | G27: -6.5 | H27: =IF(E27=0,0,MAX(0,NG-G27)) -> 5.8 | I27: =H27*E27+F27*(WS_STR*H27+SLOPE_STR*H27^2/2)+PI()*(WS_STR^2*H27+WS_STR*SLOPE_STR*H27^2+SLOPE_STR^2*H27^3/3) -> 7851.0588 | J27: =MAX(0,I27-E27*H27) -> 3854.2788 | K27: 736.3 | L27: 0 | M27: Allowance: footprint x PILE_DENS | N27: =ROUNDUP(MAX(E27,K27)*PILE_DENS,0) -> 74
A28: BLOW | B28: AW-BLOW | C28: Air blower building | D28: Civil Guide Rev01 coordination reconstruction | E28: 0 | F28: 0 | G28: -0.05 | H28: =IF(E28=0,0,MAX(0,NG-G28)) -> 0 | I28: =H28*E28+F28*(WS_STR*H28+SLOPE_STR*H28^2/2)+PI()*(WS_STR^2*H28+WS_STR*SLOPE_STR*H28^2+SLOPE_STR^2*H28^3/3) -> 0 | J28: =MAX(0,I28-E28*H28) -> 0 | K28: 413.4 | L28: 0 | M28: Allowance: footprint x PILE_DENS | N28: =ROUNDUP(MAX(E28,K28)*PILE_DENS,0) -> 42
A29: THK | B29: AW-THK-A | C29: Primary sludge thickener A | D29: Structural template available | E29: 490.1 | F29: 78.5 | G29: -1.37 | H29: =IF(E29=0,0,MAX(0,NG-G29)) -> 0.67 | I29: =H29*E29+F29*(WS_STR*H29+SLOPE_STR*H29^2/2)+PI()*(WS_STR^2*H29+WS_STR*SLOPE_STR*H29^2+SLOPE_STR^2*H29^3/3) -> 412.3199 | J29: =MAX(0,I29-E29*H29) -> 83.952902 | K29: 508.8 | L29: 41 | M29: Model (display stubs) | N29: =L29 -> 41
A30: THK | B30: AW-THK-B | C30: Primary sludge thickener B | D30: Structural template available | E30: 490.1 | F30: 78.5 | G30: -1.37 | H30: =IF(E30=0,0,MAX(0,NG-G30)) -> 0.67 | I30: =H30*E30+F30*(WS_STR*H30+SLOPE_STR*H30^2/2)+PI()*(WS_STR^2*H30+WS_STR*SLOPE_STR*H30^2+SLOPE_STR^2*H30^3/3) -> 412.3199 | J30: =MAX(0,I30-E30*H30) -> 83.952902 | K30: 508.8 | L30: 41 | M30: Model (display stubs) | N30: =L30 -> 41
A31: THK | B31: AW-THK-C | C31: Primary sludge thickener C | D31: Structural template available | E31: 490.1 | F31: 78.5 | G31: -1.37 | H31: =IF(E31=0,0,MAX(0,NG-G31)) -> 0.67 | I31: =H31*E31+F31*(WS_STR*H31+SLOPE_STR*H31^2/2)+PI()*(WS_STR^2*H31+WS_STR*SLOPE_STR*H31^2+SLOPE_STR^2*H31^3/3) -> 412.3199 | J31: =MAX(0,I31-E31*H31) -> 83.952902 | K31: 508.8 | L31: 41 | M31: Model (display stubs) | N31: =L31 -> 41
A32: THK | B32: AW-THK-D | C32: Primary sludge thickener D | D32: Structural template available | E32: 490.1 | F32: 78.5 | G32: -1.37 | H32: =IF(E32=0,0,MAX(0,NG-G32)) -> 0.67 | I32: =H32*E32+F32*(WS_STR*H32+SLOPE_STR*H32^2/2)+PI()*(WS_STR^2*H32+WS_STR*SLOPE_STR*H32^2+SLOPE_STR^2*H32^3/3) -> 412.3199 | J32: =MAX(0,I32-E32*H32) -> 83.952902 | K32: 508.8 | L32: 41 | M32: Model (display stubs) | N32: =L32 -> 41
A33: DIG | B33: AW-DIG-01 | C33: Digester 01 — anaerobic | D33: Mixed-source provisional coordination envelope | E33: 671 | F33: 92.3 | G33: -1.79 | H33: =IF(E33=0,0,MAX(0,NG-G33)) -> 1.09 | I33: =H33*E33+F33*(WS_STR*H33+SLOPE_STR*H33^2/2)+PI()*(WS_STR^2*H33+WS_STR*SLOPE_STR*H33^2+SLOPE_STR^2*H33^3/3) -> 926.31769 | J33: =MAX(0,I33-E33*H33) -> 194.92769 | K33: 1325.2 | L33: 0 | M33: Allowance: footprint x PILE_DENS | N33: =ROUNDUP(MAX(E33,K33)*PILE_DENS,0) -> 133
A34: DIG | B34: AW-DIG-02 | C34: Digester 02 — anaerobic | D34: Mixed-source provisional coordination envelope | E34: 671 | F34: 92.3 | G34: -1.79 | H34: =IF(E34=0,0,MAX(0,NG-G34)) -> 1.09 | I34: =H34*E34+F34*(WS_STR*H34+SLOPE_STR*H34^2/2)+PI()*(WS_STR^2*H34+WS_STR*SLOPE_STR*H34^2+SLOPE_STR^2*H34^3/3) -> 926.31769 | J34: =MAX(0,I34-E34*H34) -> 194.92769 | K34: 1325.2 | L34: 0 | M34: Allowance: footprint x PILE_DENS | N34: =ROUNDUP(MAX(E34,K34)*PILE_DENS,0) -> 133
A35: DIG | B35: AW-DIG-03 | C35: Digester 03 — anaerobic | D35: Mixed-source provisional coordination envelope | E35: 671 | F35: 92.3 | G35: -1.79 | H35: =IF(E35=0,0,MAX(0,NG-G35)) -> 1.09 | I35: =H35*E35+F35*(WS_STR*H35+SLOPE_STR*H35^2/2)+PI()*(WS_STR^2*H35+WS_STR*SLOPE_STR*H35^2+SLOPE_STR^2*H35^3/3) -> 926.31769 | J35: =MAX(0,I35-E35*H35) -> 194.92769 | K35: 1325.2 | L35: 0 | M35: Allowance: footprint x PILE_DENS | N35: =ROUNDUP(MAX(E35,K35)*PILE_DENS,0) -> 133
A36: DIG | B36: AW-DIG-04 | C36: Digester 04 — anaerobic | D36: Mixed-source provisional coordination envelope | E36: 671 | F36: 92.3 | G36: -1.79 | H36: =IF(E36=0,0,MAX(0,NG-G36)) -> 1.09 | I36: =H36*E36+F36*(WS_STR*H36+SLOPE_STR*H36^2/2)+PI()*(WS_STR^2*H36+WS_STR*SLOPE_STR*H36^2+SLOPE_STR^2*H36^3/3) -> 926.31769 | J36: =MAX(0,I36-E36*H36) -> 194.92769 | K36: 1325.2 | L36: 0 | M36: Allowance: footprint x PILE_DENS | N36: =ROUNDUP(MAX(E36,K36)*PILE_DENS,0) -> 133
A37: DIG | B37: AW-DIG-05 | C37: Digester 05 — anaerobic | D37: Mixed-source provisional coordination envelope | E37: 671 | F37: 92.3 | G37: -1.79 | H37: =IF(E37=0,0,MAX(0,NG-G37)) -> 1.09 | I37: =H37*E37+F37*(WS_STR*H37+SLOPE_STR*H37^2/2)+PI()*(WS_STR^2*H37+WS_STR*SLOPE_STR*H37^2+SLOPE_STR^2*H37^3/3) -> 926.31769 | J37: =MAX(0,I37-E37*H37) -> 194.92769 | K37: 1325.2 | L37: 0 | M37: Allowance: footprint x PILE_DENS | N37: =ROUNDUP(MAX(E37,K37)*PILE_DENS,0) -> 133
A38: DIG | B38: AW-DIG-06 | C38: Digester 06 — anaerobic | D38: Mixed-source provisional coordination envelope | E38: 671 | F38: 92.3 | G38: -1.79 | H38: =IF(E38=0,0,MAX(0,NG-G38)) -> 1.09 | I38: =H38*E38+F38*(WS_STR*H38+SLOPE_STR*H38^2/2)+PI()*(WS_STR^2*H38+WS_STR*SLOPE_STR*H38^2+SLOPE_STR^2*H38^3/3) -> 926.31769 | J38: =MAX(0,I38-E38*H38) -> 194.92769 | K38: 1325.2 | L38: 0 | M38: Allowance: footprint x PILE_DENS | N38: =ROUNDUP(MAX(E38,K38)*PILE_DENS,0) -> 133
A39: DIG | B39: AW-DIG-07 | C39: Digester 07 — anaerobic | D39: Mixed-source provisional coordination envelope | E39: 671 | F39: 92.3 | G39: -1.79 | H39: =IF(E39=0,0,MAX(0,NG-G39)) -> 1.09 | I39: =H39*E39+F39*(WS_STR*H39+SLOPE_STR*H39^2/2)+PI()*(WS_STR^2*H39+WS_STR*SLOPE_STR*H39^2+SLOPE_STR^2*H39^3/3) -> 926.31769 | J39: =MAX(0,I39-E39*H39) -> 194.92769 | K39: 1325.2 | L39: 0 | M39: Allowance: footprint x PILE_DENS | N39: =ROUNDUP(MAX(E39,K39)*PILE_DENS,0) -> 133
A40: DIG | B40: AW-DIG-08 | C40: Digester 08 — anaerobic | D40: Mixed-source provisional coordination envelope | E40: 671 | F40: 92.3 | G40: -1.79 | H40: =IF(E40=0,0,MAX(0,NG-G40)) -> 1.09 | I40: =H40*E40+F40*(WS_STR*H40+SLOPE_STR*H40^2/2)+PI()*(WS_STR^2*H40+WS_STR*SLOPE_STR*H40^2+SLOPE_STR^2*H40^3/3) -> 926.31769 | J40: =MAX(0,I40-E40*H40) -> 194.92769 | K40: 1325.2 | L40: 0 | M40: Allowance: footprint x PILE_DENS | N40: =ROUNDUP(MAX(E40,K40)*PILE_DENS,0) -> 133
A41: GHT | B41: AW-GHT-01 | C41: Gas holder 01 - civil plinth | D41: Tender provisional civil plinth only; equipment unmodelled | E41: 452.4 | F41: 75.4 | G41: -1.5 | H41: =IF(E41=0,0,MAX(0,NG-G41)) -> 0.8 | I41: =H41*E41+F41*(WS_STR*H41+SLOPE_STR*H41^2/2)+PI()*(WS_STR^2*H41+WS_STR*SLOPE_STR*H41^2+SLOPE_STR^2*H41^3/3) -> 465.16757 | J41: =MAX(0,I41-E41*H41) -> 103.24757 | K41: 452.4 | L41: 0 | M41: Allowance: footprint x PILE_DENS | N41: =ROUNDUP(MAX(E41,K41)*PILE_DENS,0) -> 46
...

Sheet Pipes
A1: Underground pipework - quantities per line
A2: Lengths, sizes and fittings from the v3 package workbook (21 Oct 2026). Excavation, sheet piles, piled slab, piles, backfill, dewatering and flotation from the sequence workbook (22 Oct 2026: GWL -1.50, all pipes on piled slabs). Surround is a formula.
A4: Line | B4: Material | C4: Printed size | D4: Planning OD (m) | E4: 3D length (m) | F4: Packages | G4: Tie-in / connection ends | H4: Elbow 30 | I4: Elbow 45 | J4: Elbow 90 | K4: Elbow (angle not stated) | L4: Flange | M4: Reducer | N4: Tee | O4: Stub end | P4: Excavation shored (m3) | Q4: Excavation open cut (m3) | R4: Sheet pile area (m2) | S4: Sheet pile wall (m) | T4: Piled slab concrete (m3) | U4: Pipe-support piles (no.) | V4: Backfill (m3) | W4: Granular surround (m3) | X4: Dewatered length (m) | Y4: Dewatering package-days | Z4: Pipe length needing anchor straps (m) | AA4: Crossings to locate (no. packages)
A5: UG-01 | B5: GRP | C5: DN2500 | D5: 2.586 | E5: 324.28767 | F5: 3 | G5: 2 | H5: 0 | I5: 10 | J5: 5 | K5: 0 | L5: 0 | M5: 0 | N5: 0 | O5: 0 | P5: 7889.5844 | Q5: 0 | R5: 8811.6433 | S5: 648.55181 | T5: 546.25229 | U5: 215 | V5: 5822.9194 | W5: =E5*((D5+2*WS_PIPE)*(D5+SURR_ABOVE)-PI()*D5^2/4) -> 2588.7649 | X5: 324.2759 | Y5: 241 | Z5: 0 | AA5: 1
A6: UG-02 | B6: GRP | C6: DN2000 | D6: 2.07 | E6: 267.36571 | F6: 5 | G6: 2 | H6: 0 | I6: 0 | J6: 4 | K6: 0 | L6: 0 | M6: 1 | N6: 0 | O6: 0 | P6: 5798.4474 | Q6: 0 | R6: 6300.5053 | S6: 534.72387 | T6: 409.16794 | U6: 194 | V6: 4496.5749 | W6: =E6*((D6+2*WS_PIPE)*(D6+SURR_ABOVE)-PI()*D6^2/4) -> 1679.203 | X6: 267.36193 | Y6: 464 | Z6: 0 | AA6: 3
A7: UG-03 | B7: GRP | C7: DN2000 | D7: 2.07 | E7: 186.06485 | F7: 5 | G7: 1 | H7: 0 | I7: 0 | J7: 4 | K7: 0 | L7: 0 | M7: 1 | N7: 0 | O7: 0 | P7: 4033.5588 | Q7: 0 | R7: 4509.5383 | S7: 372.11833 | T7: 282.21789 | U7: 138 | V7: 3146.2977 | W7: =E7*((D7+2*WS_PIPE)*(D7+SURR_ABOVE)-PI()*D7^2/4) -> 1168.5891 | X7: 186.05917 | Y7: 341 | Z7: 0 | AA7: 5
A8: UG-04 | B8: GRP | C8: DN2000 | D8: 2.07 | E8: 22.703603 | F8: 2 | G8: 1 | H8: 4 | I8: 0 | J8: 0 | K8: 0 | L8: 0 | M8: 1 | N8: 0 | O8: 0 | P8: 472.84193 | Q8: 0 | R8: 547.78839 | S8: 45.309781 | T8: 33.90477 | U8: 22 | V8: 367.6422 | W8: =E8*((D8+2*WS_PIPE)*(D8+SURR_ABOVE)-PI()*D8^2/4) -> 142.59105 | X8: 22.65489 | Y8: 129 | Z8: 0 | AA8: 2
A9: UG-05 | B9: GRP | C9: DN2200 | D9: 2.276 | E9: 306.5183 | F9: 5 | G9: 1 | H9: 0 | I9: 0 | J9: 6 | K9: 0 | L9: 0 | M9: 0 | N9: 0 | O9: 0 | P9: 2988.4682 | Q9: 3231.1135 | R9: 2891.2441 | S9: 413.03487 | T9: 498.52185 | U9: 220 | V9: 4499.2523 | W9: =E9*((D9+2*WS_PIPE)*(D9+SURR_ABOVE)-PI()*D9^2/4) -> 2129.2218 | X9: 306.51743 | Y9: 393 | Z9: 0 | AA9: 3
A10: UG-06 | B10: GRP | C10: DN2200 | D10: 2.276 | E10: 299.90736 | F10: 5 | G10: 1 | H10: 0 | I10: 1 | J10: 9 | K10: 0 | L10: 0 | M10: 0 | N10: 0 | O10: 0 | P10: 4331.4844 | Q10: 0 | R10: 4198.7008 | S10: 599.8144 | T10: 487.3202 | U10: 216 | V10: 2651.9096 | W10: =E10*((D10+2*WS_PIPE)*(D10+SURR_ABOVE)-PI()*D10^2/4) -> 2083.2991 | X10: 299.9072 | Y10: 436 | Z10: 0 | AA10: 3
A11: UG-07 | B11: GRP | C11: DN2000 | D11: 2.07 | E11: 86.76427 | F11: 4 | G11: 1 | H11: 0 | I11: 4 | J11: 0 | K11: 0 | L11: 0 | M11: 1 | N11: 0 | O11: 0 | P11: 1012.1648 | Q11: 558.59565 | R11: 1093.9102 | S11: 128.93194 | T11: 133.07205 | U11: 70 | V11: 1146.1724 | W11: =E11*((D11+2*WS_PIPE)*(D11+SURR_ABOVE)-PI()*D11^2/4) -> 544.92711 | X11: 86.727325 | Y11: 268 | Z11: 0 | AA11: 4
A12: UG-07A | B12: HDPE | C12: OD1600 | D12: 1.655 | E12: 371.36636 | F12: 12 | G12: 4 | H12: 0 | I12: 10 | J12: 5 | K12: 5 | L12: 4 | M12: 2 | N12: 0 | O12: 0 | P12: 1476.1689 | Q12: 2835.2946 | R12: 2091.5403 | S12: 334.37513 | T12: 429.05694 | U12: 284 | V12: 3370.4252 | W12: =E12*((D12+2*WS_PIPE)*(D12+SURR_ABOVE)-PI()*D12^2/4) -> 1854.7149 | X12: 370.92538 | Y12: 960 | Z12: 0 | AA12: 7
A13: UG-12 | B13: GRP | C13: DN2000 | D13: 2.07 | E13: 233.26078 | F13: 8 | G13: 1 | H13: 4 | I13: 4 | J13: 0 | K13: 0 | L13: 0 | M13: 1 | N13: 0 | O13: 0 | P13: 3705.2633 | Q13: 1252.1155 | R13: 3920.1678 | S13: 345.41678 | T13: 357.15267 | U13: 184 | V13: 3817.4356 | W13: =E13*((D13+2*WS_PIPE)*(D13+SURR_ABOVE)-PI()*D13^2/4) -> 1465.0054 | X13: 232.70839 | Y13: 598 | Z13: 0 | AA13: 8
A14: UG-12A | B14: HDPE | C14: DN1600 as printed | D14: 1.633 | E14: 346.3713 | F14: 12 | G14: 4 | H14: 0 | I14: 8 | J14: 2 | K14: 2 | L14: 3 | M14: 2 | N14: 0 | O14: 0 | P14: 530.14334 | Q14: 3987.1034 | R14: 761.07632 | S14: 152.21526 | T14: 408.90493 | U14: 268 | V14: 3594.0056 | W14: =E14*((D14+2*WS_PIPE)*(D14+SURR_ABOVE)-PI()*D14^2/4) -> 1706.9789 | X14: 346.3712 | Y14: 1210 | Z14: 0 | AA14: 7
A15: UG-15 | B15: GRP | C15: DN2000 | D15: 2.07 | E15: 167.99808 | F15: 6 | G15: 1 | H15: 0 | I15: 2 | J15: 2 | K15: 0 | L15: 0 | M15: 1 | N15: 0 | O15: 0 | P15: 3141.7809 | Q15: 0 | R15: 3359.9523 | S15: 335.99523 | T15: 255.75723 | U15: 132 | V15: 2334.2621 | W15: =E15*((D15+2*WS_PIPE)*(D15+SURR_ABOVE)-PI()*D15^2/4) -> 1055.1199 | X15: 167.99761 | Y15: 196 | Z15: 0 | AA15: 3
A16: UG-15A | B16: HDPE | C16: OD1600 | D16: 1.655 | E16: 259.21903 | F16: 10 | G16: 4 | H16: 0 | I16: 8 | J16: 2 | K16: 7 | L16: 3 | M16: 2 | N16: 0 | O16: 0 | P16: 3220.4107 | Q16: 290.72247 | R16: 4261.5826 | S16: 477.46759 | T16: 298.2358 | U16: 204 | V16: 2860.2496 | W16: =E16*((D16+2*WS_PIPE)*(D16+SURR_ABOVE)-PI()*D16^2/4) -> 1294.6176 | X16: 258.7338 | Y16: 737 | Z16: 0 | AA16: 7
... A49: UG-28A | B49: HDPE | C49: OD315 | D49: 0.315 | E49: 17.837379 | F49: 1 | G49: 2 | H49: 0 | I49: 0 | J49: 3 | K49: 0 | L49: 0 | M49: 1 | N49: 1 | O49: 2 | P49: 0 | Q49: 0 | R49: 0 | S49: 0 | T49: 0 | U49: 7 | V49: 0 | W49: =E49*((D49+2*WS_PIPE)*(D49+SURR_ABOVE)-PI()*D49^2/4) -> 24.005435 | X49: 0 | Y49: 0 | Z49: 0 | AA49: 1
A50: Total | E50: =SUM(E5:E49) -> 8168.8302 | F50: =SUM(F5:F49) -> 201 | G50: =SUM(G5:G49) -> 90 | H50: =SUM(H5:H49) -> 27 | I50: =SUM(I5:I49) -> 219 | J50: =SUM(J5:J49) -> 88 | K50: =SUM(K5:K49) -> 58 | L50: =SUM(L5:L49) -> 43 | ... AA50: =SUM(AA5:AA49) -> 129

Sheet Exclusions
A1: Exclusions, gaps and how to improve the estimate
A3: Item | B3: Status
A4: Preliminaries, site establishment, supervision, insurances, contingency | B4: Not included.
A5: Mechanical, electrical, instrumentation and process equipment | B5: Not included. Equipment envelopes in the model are listed as counts only.
A6: Architecture and finishes (doors, windows, cladding, finishes, MEP in buildings) | B6: Not included; building walls are measured as concrete envelopes (material TBC).
A7: Pile lengths | B7: No pile design lengths in the model (display stubs). Piles are counted, not measured in metres.
A8: Piles for structures without pile layouts | B8: Allowance = footprint x PILE_DENS (calibrated on aeration). Replace with pile designs.
A9: Pipe-support piles | B9: Placeholder layout (rows at 3 m, 2 per row for OD >= 1.0 m). Replace with design.
A10: Reinforcement | B10: Ratios per element class (Inputs). Only the aeration raft ratio is evidence-based.
A11: Dewatering and temporary works for structures | B11: Not quantified (no temporary works design); pipe dewatering and sheet piles are included.
A12: Existing structures and boundaries not in the model | B12: Existing PST, bypass / outfall chambers, treated effluent pump station, inlet / outlet boundaries, primary and thickened sludge pump stations, sludge flowmeter chambers: not measured.
A13: Structures modelled from tender / provisional envelopes | B13: Digesters, gas holders, sludge buildings, pump stations, CHP, THP, final dewatering: Confidence D.
A14: Typical structures | B14: FST A-L and thickeners A-D are typical structures placed 12 and 4 times; tank-specific differences not captured.
... A18: Roads, drainage, landscaping, fencing, utilities, cable ducts | B18: Not in the model - not included.
