Workbook

Sheet Read Me
A1: Alex West - underground pipe construction sequence and methodology
A2: Prepared 22 Oct 2026 by Claude for Mohamed. Planning workbook: not a design, temporary-works or construction approval.
A4: What it is
A5: A sequence, methodology and logic-linked activity programme for the 201 pipe packages (45 lines) of the v3 package workbook, re-checked for groundwater at -1.50 and with every pipe carried on piles and a piled slab.
A6: Inputs used
A7: 1. Alex-West-Pipe-Execution-Packages-All-Lines.xlsx (v3, 21 Oct 2026): packages, pieces, levels, nearest structures and piles, holds, sequence notes.
A8: 2. Alex-West-Combined-Coordination.blend (19 Oct 2026): aeration pile status for 3,672 piles (data date 17 Oct 2026), agreed aeration piling zone order, recorded weekly piling production, structure register (stage and open gaps). Check: pile counts near UG-02-S03 reproduce the package workbook (31 within 15 m, 18 pending).
A9: 3. Decisions (Mohamed, 22 Oct 2026): groundwater level -1.50; all pipes need piles and foundations; shoring where needed.
A10: 4. The web viewer link could not be opened from this environment (host blocked); the .blend file was used instead.
A11: Sheets
A12: Methodology - step-by-step method, plant, hold points and the sequencing rules.
A13: Inputs - levels, groundwater, slopes, pile layout, gates and productivity (yellow = edit).
... A30: Blue text = input or source data; black = formula; green = formula pulling from another sheet; yellow fill = edit.

Sheet Methodology
A1: Construction methodology - buried GRP / HDPE pipes on piled slabs, groundwater at -1.50
A2: Planning methodology for sequencing and resourcing. Not a temporary-works design or a method statement for approval.
A4: Step | B4: Activity (code) | C4: Method | D4: Plant / crew | E4: Hold points and checks | F4: Quantity / duration basis
A5: 1 | B5: Release (A010) | C5: Package released only when: DLU-002 approved (Rev 03 is Issued for Approval); pile and slab design approved; the connected structure is ready for tie-in packages; aeration piling in the adjacent zone is complete where open aeration piles are within 15 m; unassigned crossing pipes identified (UG-01-S02, UG-02-S04, UG-03-S03). | D5: Planning / engineering | E5: IFC drawing; pile design; permit to dig; structure handover certificate; aeration zone piling complete. | F5: Gates on Inputs, Structures and Aeration sheets.
A6: 2 | B6: Set-out and working platform (A020) | C6: Survey pipe axis, slab edges, pile positions and sheet lines. Trial pits / scanning at every crossing listed on Packages. Granular working platform at NG for piling rigs and cranes on very soft clay; platform designed for rig track pressure. | D6: Survey team, dozer, roller | E6: Platform bearing check (plate test) before rig access. | F6: Plan length / R_PLAT.
A7: 3 | B7: Pipe-support piling (A030) | C7: All pipes are carried on piles and a piled slab. Install piles from the platform at NG BEFORE excavation (CFA or bored, 600 mm assumed), concreting to above cut-off and leaving the empty-bore length to the slab soffit. Rigs follow the front order; near structures and aeration piles keep the agreed clearances. | D7: 1-2 rigs per front (Fronts sheet); site actual 5.4 piles / rig / day, 5.0 used | E7: Pile records, integrity tests on every pile, preliminary load test before production. | F7: Piles = (length / PILE_SP + 1) x piles per row - placeholder until pile design.
A8: 4 | B8: Sheet piles (A040) | C8: Where the Piece check says sheet piles (open cut does not fit beside a structure / pile, or excavation is deeper than MAXOC below GWL): install interlocking steel sheets both sides after piling, with a toe in the soft clay for cut-off and base stability. Press-in (silent) method within 10 m of structures and fresh piles to limit vibration. | D8: Sheet pile gang with vibro / press-in rig and crane | E8: Temporary works design: embedment, struts, base heave, hydraulic cut-off. | F8: Wall = 2 x shored length; sheet length = depth x SHEET_RATIO.
A9: 5 | B9: Dewatering (A050) | C9: Groundwater at -1.50 and excavation bottoms down to -7.6 (199 of 201 packages below GWL, up to 6.1 m) mean almost every package is dewatered. Wellpoints along the trench to 0.5 m below formation; deep wells or two-stage wellpoints where drawdown exceeds 4.5 m. Draw down for at least DW_DRAW days before excavation. Monitor levels next to existing structures and fresh piles (settlement / negative skin friction). | D9: Dewatering subcontractor, standby pumps and power | E9: Piezometers; settlement markers on structures within 15 m; discharge permit and silt treatment. | F9: Drawdown = GWL - (R - DD_BELOW); method on Packages.
A10: 6 | B10: Excavation and strutting (A060) | C10: Excavate in layers, installing walings and struts as each level is reached. Keep the excavator off the edge in soft clay; stockpile away from the trench. Excavate evenly around the installed piles so they are not pushed sideways. Deeper lines are excavated, laid and backfilled before a shallower line in the same corridor; lines in a shared trench are opened together. | D10: Long-reach excavator / clamshell, trucks | E10: Formation inspection; pile head exposure survey; strut loads. | F10: Shored m3 / R_EXS + open-cut m3 / R_EXO.
A11: 7 | B11: Piled slab (A070) | C11: Break down pile heads to cut-off, blinding, reinforcement with pile starter bars, cast the 0.50 m piled slab (pipe cradle or anchor straps cast in where the flotation check needs them). Cure before pipe load. | D11: Concrete gang, pump | E11: Pile head inspection; rebar inspection before pour; cube results. | F11: Length / R_SLAB + SLAB_CURE.
A12: 8 | B12: Pipe laying and jointing (A080) | C12: Lay from the downstream end upwards (gravity lines). GRP: bell and spigot joints with a crane and lifting beam; HDPE: butt fusion off-line, lowered in strings. Fittings and thrust restraint as drawn. Tie-in packages are laid last as the closure to the structure, once the structure is ready. | D12: Pipe crew + crane per front; fusion machine for HDPE | E12: Joint test per joint (GRP); fusion records (HDPE); alignment and level survey. | F12: Length / pipe rate by OD + fittings x FIT_D + TIE_D at tie-ins.
A13: 9 | B13: Surround and testing (A090) | C13: Granular haunch and surround placed and compacted evenly both sides (flexible pipes). Line test by section. | D13: Pipe crew | E13: Deflection check (GRP); hydrostatic / air test. | F13: TEST_D + length / R_TEST.
A14: 10 | B14: Backfill (A100) | C14: Backfill in layers to NG, removing struts progressively as the fill reaches each level. Shared-trench pipes are all laid before backfill starts. Keep dewatering running until the flotation check is met (Packages column "Flotation action"): empty pipes below -1.50 can float. | D14: Excavator, compactors | E14: Compaction tests; flotation check before switching off pumps. | F14: Backfill m3 / R_BF.
A15: 11 | B15: Dewatering off, extract sheets (A110) | C15: Switch off and remove dewatering only after the fill is heavy enough (or the pipe is strapped to the slab). Extract sheet piles slowly, grouting voids near pipes and structures. Reinstate the platform / surface. | D15: Crane with vibro extractor | E15: Survey pipe level after pumps off; settlement monitoring. | F15: Wall m / R_EXT.
B16: Sequencing rules (whole network) | C16: 1) Eight fronts by system (Fronts sheet). A shared-trench corridor that crosses systems is built by one front (the one holding most of its length; 30 packages moved). 2) Within a front: deeper lines first, downstream first; shared-trench packages back to back along the corridor. 3) Deeper-first links between packages within 8 m with excavation bottoms more than 1 m apart. 4) Shared trench (bottoms within 1 m): excavate together, backfill only after all its pipes are laid (6 such holds are site coordination items - see Packages). 5) Set-out runs one package ahead of piling; dewatering is timed so drawdown completes when the excavation crew is free. 6) Tie-ins follow the adjacent run, wait for the structure and close the line. 7) Packages within 15 m of open aeration piles wait for that zone, in the agreed zone order. 8) Pipe piling waits for pile design approval; nothing starts before DLU-002 approval. | E16: Pending decisions: GWL design value confirmation; slope and depth-limit rules; pile layout; structure readiness dates.
B17: Rig planning note | C17: 8 rigs are on aeration piling at about 5.4 piles / rig / working day (measured from the model). 1,587 open aeration piles remain; at that rate they finish around end November 2026 (Aeration sheet). Pipe-support piling (about 5,800 piles on the placeholder layout) peaks at about 13 equivalent rigs in the first months (Programme sheet, row Rigs), so releasing the aeration rigs to the pipe fronts is the natural hand-over.

Sheet Inputs
A1: Inputs - levels, ground, groundwater, piles, programme gates and productivity
A2: Yellow = edit. Every quantity, method flag, duration and date in this workbook recalculates from these cells.
A4: Name | B4: Description | C4: Value | D4: Unit | E4: Source / status
A5: Levels and ground
A6: NG | B6: Adopted natural ground level | C6: -0.7 | D6: m | E6: Package workbook Inputs (D-004, Mohamed 20 Oct 2026). Single site value.
A7: FL | B7: Finished ground level | C7: 1 | D7: m | E7: Package workbook Inputs (D-004; DLU sections FGL +1.00).
A8: GWL | B8: Groundwater level for design of temporary works | C8: -1.5 | D8: m | E8: Mohamed, 22 Oct 2026.
A9: SLAB | B9: Piled slab + blinding below external pipe bottom (excavation bottom R = pipe bottom - SLAB) | C9: 0.5 | D9: m | E9: D-001, user-stated basis. All pipes on piles and a piled slab (Mohamed, 22 Oct 2026). No pile/slab design yet.
A10: SLABOVH | B10: Piled slab overhang beyond pipe outside, each side | C10: 0.5 | D10: m | E10: ASSUMPTION for concrete quantity only.
A11: WS | B11: Working space, pipe outside to trench toe / sheet line | C11: 1 | D11: m | E11: AGREED by Mohamed, 21 Oct 2026.
A12: SLOPE_A | B12: Open-cut side slope above GWL (H per 1 V) | C12: 1.5 | D12: H:V | E12: ASSUMPTION (very soft silty clay). Package workbook value.
A13: SLOPE_B | B13: Open-cut side slope below GWL, dewatered (H per 1 V) | C13: 2 | D13: H:V | E13: ASSUMPTION: flatter below water in soft clay. Geotechnical confirmation needed.
A14: MAXOC | B14: Maximum excavation depth below GWL allowed in open cut (deeper = sheet piles regardless of space) | C14: 2.5 | D14: m | E14: ASSUMPTION: base heave / slope stability limit in soft clay below water. See Sensitivity sheet.
A15: DD_BELOW | B15: Drawdown target below excavation formation | C15: 0.5 | D15: m | E15: Planning rule of thumb.
A16: WP_LIMIT | B16: Maximum drawdown for single-stage wellpoints | C16: 4.5 | D16: m | E16: Planning rule of thumb; deeper needs deep wells / two stages.
A17: GAM_D | B17: Unit weight of backfill above GWL | C17: 18 | D17: kN/m3 | E17: ASSUMPTION.
... A20: FOS_FLOT | B20: Required factor of safety against pipe flotation (empty pipe, pipe weight ignored) | C20: 1.1 | D20: - | E20: Planning check value.
A21: Pipe-support piles and sheet piles (no pile design available - layout is a planning placeholder)
A22: PILE_SP | B22: Longitudinal spacing of pile rows under the pipe slab | C22: 3 | D22: m | E22: ASSUMPTION - replace with pile design.
A23: PILE_THR | B23: Outside diameter at or above which two piles per row are used | C23: 1 | D23: m | E23: ASSUMPTION.
A24: PILE_N_SMALL | B24: Piles per row below the threshold | C24: 1 | D24: no. | E24: ASSUMPTION.
A25: PILE_N_LARGE | B25: Piles per row at or above the threshold | C25: 2 | D25: no. | E25: ASSUMPTION.
A26: SHEET_RATIO | B26: Sheet pile length / excavation depth from NG (embedment in soft clay) | C26: 2 | D26: - | E26: ASSUMPTION - temporary works design to confirm.
A27: Programme gates and calendar
A28: START | B28: Pipe works mobilisation (earliest start of any package) | C28: 46357 | D28: date | E28: EXAMPLE - replace with the planned mobilisation date.
A29: D_DLU | B29: DLU-002 approved / IFC (Rev 03 is Issued for Approval) | C29: 46357 | D29: date | E29: Not yet known - currently equal to START (not constraining). Enter the forecast approval date.
A30: D_PILEDES | B30: Pipe pile and slab design approved | C30: 46357 | D30: date | E30: Not yet known - currently equal to START (not constraining). Gates all pipe piling.
A31: D_XING | B31: Unassigned crossing pipes P0114 / P0117 / P0279 identified | C31: 46357 | D31: date | E31: Not yet known - gates excavation of UG-01-S02, UG-02-S04, UG-03-S03.
A32: WD | B32: Working days per week | C32: 6 | D32: days | E32: Site calendar Sat-Thu (calendar days = working days x 7 / WD).
A33: LADDER | B33: Overlap within a package: successor starts after this share of its predecessor | C33: 0.3 | D33: - | E33: Planning rule (start-to-start ladder). 1.0 = finish-to-start.
A34: FFLAG | B34: Finish-to-finish lag between consecutive activities in a package | C34: 2 | D34: cal. days | E34: Planning rule.
A35: Productivity per crew / rig (per working day)
A36: R_PLAT | B36: Set-out, crossing survey and working platform | C36: 80 | D36: m/day | E36: ASSUMPTION.
A37: R_PILE | B37: Pipe-support piles per rig (600 mm assumed) | C37: 5 | D37: piles/day | E37: Site actual on aeration 600 mm piling = 5.4 (last 4 full weeks, Aeration sheet). 5.0 used for the longer empty bore from NG.
A38: R_SHEET | B38: Sheet pile installation (vibro / press-in near structures) | C38: 25 | D38: m wall/day | E38: ASSUMPTION.
A39: R_DW | B39: Dewatering installation along the trench | C39: 40 | D39: m/day | E39: ASSUMPTION.
A40: DW_DRAW | B40: Drawdown period before excavation | C40: 7 | D40: days | E40: ASSUMPTION - soft silty clay is slow to drain.
A41: R_EXS | B41: Excavation in a strutted sheet-piled trench | C41: 250 | D41: m3/day | E41: ASSUMPTION.
A42: R_EXO | B42: Excavation in dewatered open cut | C42: 450 | D42: m3/day | E42: ASSUMPTION.
A43: R_SLAB | B43: Pile trimming, blinding and piled slab (rebar, form, pour) | C43: 12 | D43: m/day | E43: ASSUMPTION.
...

Sheet Aeration
A1: Aeration piling status and zone forecast (from the 3D model)
A2: Source: Alex-West-Combined-Coordination.blend, scene "AW-AER Piles Actual - 2026-10-18"; tracking data date 17 Oct 2026. Done = recorded execution, not acceptance. Agreed piling order (18 Oct 2026): Zones 1, 2, 3, then 5 and 4 together, then 6, then 7, then 8.
A4: Zone | B4: Group order | C4: Done | D4: Pending | E4: Defect | F4: Unknown | G4: Open piles to complete (pending + defect) | H4: Cumulative open piles in agreed order | I4: Forecast zone piling complete | J4: Pipe packages gated
A5: 1 | B5: 1 | C5: 470 | D5: 6 | E5: 2 | F5: 0 | G5: =D5+E5 -> 8 | H5: =SUMIFS($G$5:$G$12,$B$5:$B$12,"<="&B5) -> 8 | I5: =AER_DATA+ROUNDUP(H5/(AER_RIGS*AER_RATE)*7/WD,0) -> 46313 | J5: 0
A6: 2 | B6: 2 | C6: 518 | D6: 41 | E6: 2 | F6: 3 | G6: =D6+E6 -> 43 | H6: =SUMIFS($G$5:$G$12,$B$5:$B$12,"<="&B6) -> 51 | I6: =AER_DATA+ROUNDUP(H6/(AER_RIGS*AER_RATE)*7/WD,0) -> 46314 | J6: 0
A7: 3 | B7: 3 | C7: 248 | D7: 236 | E7: 2 | F7: 0 | G7: =D7+E7 -> 238 | H7: =SUMIFS($G$5:$G$12,$B$5:$B$12,"<="&B7) -> 289 | I7: =AER_DATA+ROUNDUP(H7/(AER_RIGS*AER_RATE)*7/WD,0) -> 46320 | J7: 3
A8: 4 | B8: 4 | C8: 221 | D8: 337 | E8: 3 | F8: 0 | G8: =D8+E8 -> 340 | H8: =SUMIFS($G$5:$G$12,$B$5:$B$12,"<="&B8) -> 770 | I8: =AER_DATA+ROUNDUP(H8/(AER_RIGS*AER_RATE)*7/WD,0) -> 46333 | J8: 1
A9: 5 | B9: 4 | C9: 223 | D9: 137 | E9: 4 | F9: 0 | G9: =D9+E9 -> 141 | H9: =SUMIFS($G$5:$G$12,$B$5:$B$12,"<="&B9) -> 770 | I9: =AER_DATA+ROUNDUP(H9/(AER_RIGS*AER_RATE)*7/WD,0) -> 46333 | J9: 2
A10: 6 | B10: 5 | C10: 134 | D10: 279 | E10: 5 | F10: 0 | G10: =D10+E10 -> 284 | H10: =SUMIFS($G$5:$G$12,$B$5:$B$12,"<="&B10) -> 1054 | I10: =AER_DATA+ROUNDUP(H10/(AER_RIGS*AER_RATE)*7/WD,0) -> 46341 | J10: 0
A11: 7 | B11: 6 | C11: 121 | D11: 296 | E11: 1 | F11: 0 | G11: =D11+E11 -> 297 | H11: =SUMIFS($G$5:$G$12,$B$5:$B$12,"<="&B11) -> 1351 | I11: =AER_DATA+ROUNDUP(H11/(AER_RIGS*AER_RATE)*7/WD,0) -> 46349 | J11: 2
A12: 8 | B12: 7 | C12: 144 | D12: 236 | E12: 0 | F12: 3 | G12: =D12+E12 -> 236 | H12: =SUMIFS($G$5:$G$12,$B$5:$B$12,"<="&B12) -> 1587 | I12: =AER_DATA+ROUNDUP(H12/(AER_RIGS*AER_RATE)*7/WD,0) -> 46355 | J12: 3
A13: Total | C13: =SUM(C5:C12) -> 2079 | D13: =SUM(D5:D12) -> 1568 | E13: =SUM(E5:E12) -> 19 | F13: =SUM(F5:F12) -> 6 | G13: =SUM(G5:G12) -> 1587
A15: Production basis
A16: AER_DATA | B16: Tracking data date | G16: 46312 | H16: From model properties (Tracking_Data_Date).
A17: AER_RIGS | B17: Rigs assumed to stay on aeration piling | G17: 8 | H17: Model: 8 rigs active in the last two recorded weeks. Edit if rigs move to pipe piling earlier.
A18: AER_ACT | B18: Actual rate, last 4 full weeks (piles per rig per working day) | G18: =SUM(B31:B34)/SUM(C31:C34)/WD -> 5.4285714 | H18: Formula from the weekly table below.
A19: AER_OVR | B19: Override rate (blank = use actual) | H19: Optional.
A20: AER_RATE | B20: Rate used for the forecast | G20: =IF(AER_OVR="",AER_ACT,AER_OVR) -> 5.4285714
A23: Recorded production by week (from execution dates on the pile objects)
A24: Week from | B24: Piles executed | C24: Rigs active | D24: Piles / rig / working day
A25: 46237 | B25: 4 | C25: 2 | D25: =B25/C25/WD -> 0.33333333
A26: 46244 | B26: 46 | C26: 3 | D26: =B26/C26/WD -> 2.5555556
A27: 46251 | B27: 123 | C27: 5 | D27: =B27/C27/WD -> 4.1
A28: 46258 | B28: 210 | C28: 7 | D28: =B28/C28/WD -> 5
A29: 46265 | B29: 146 | C29: 7 | D29: =B29/C29/WD -> 3.4761905
A30: 46272 | B30: 229 | C30: 8 | D30: =B30/C30/WD -> 4.7708333
A31: 46279 | B31: 323 | C31: 9 | D31: =B31/C31/WD -> 5.9814815
A32: 46286 | B32: 316 | C32: 9 | D32: =B32/C32/WD -> 5.8518519
A33: 46293 | B33: 246 | C33: 9 | D33: =B33/C33/WD -> 4.5555556
A34: 46300 | B34: 255 | C34: 8 | D34: =B34/C34/WD -> 5.3125
A35: 46307 | B35: 200 | C35: 8 | D35: =B35/C35/WD -> 4.1666667 | E35: Week to data date (17 Oct) - may be partial; excluded from the rate.

Sheet Structures
A1: Structure readiness for pipe tie-ins
A2: Yellow = enter the date each structure is ready for a pipe tie-in (wall and penetration built, its excavation backfilled to pipe zone). Blank = not constraining. The 3D model holds no construction progress for these structures (only aeration piles), so these dates must come from the master programme.
A4: Code | B4: Structure | C4: In 3D model | D4: Model stage (manifest 19 Oct 2026) | E4: Open gaps (manifest) | F4: Ready for tie-in (date) | G4: Tie-in packages | H4: Date used
A5: AER | B5: aeration tank | C5: Yes | D5: Structural reconstruction | E5: Reconcile new CGD/calculation and held features | G5: 3 | H5: =IF(F5="",0,F5) -> 0
A6: CCT | B6: chlorine contact tank | C6: Yes | D6: Civil Guide Rev01 coordination reconstruction | E6: Guide structure; OP01/floor discrepancy; consultant comments and common datum / interfaces unverified | G6: 8 | H6: =IF(F6="",0,F6) -> 0
A7: FSTA | B7: FST A | C7: Yes | D7: Typical structural instance | E7: Tank-specific attachments, structural applicability and penetration ports | G7: 3 | H7: =IF(F7="",0,F7) -> 0
A8: FSTB | B8: FST B | C8: Yes | D8: Typical structural instance | E8: Tank-specific attachments, structural applicability and penetration ports | G8: 3 | H8: =IF(F8="",0,F8) -> 0
A9: FSTC | B9: FST C | C9: Yes | D9: Typical structural instance | E9: Tank-specific attachments, structural applicability and penetration ports | G9: 3 | H9: =IF(F9="",0,F9) -> 0
A10: FSTD | B10: FST D | C10: Yes | D10: Typical structural instance | E10: Tank-specific attachments, structural applicability and penetration ports | G10: 3 | H10: =IF(F10="",0,F10) -> 0
A11: FSTE | B11: FST E | C11: Yes | D11: Typical structural instance | E11: Tank-specific attachments, structural applicability and penetration ports | G11: 3 | H11: =IF(F11="",0,F11) -> 0
A12: FSTF | B12: FST F | C12: Yes | D12: Typical structural instance | E12: Tank-specific attachments, structural applicability and penetration ports | G12: 3 | H12: =IF(F12="",0,F12) -> 0
A13: FSTG | B13: FST G | C13: Yes | D13: Typical structural instance | E13: Tank-specific attachments, structural applicability and penetration ports | G13: 3 | H13: =IF(F13="",0,F13) -> 0
A14: FSTH | B14: FST H | C14: Yes | D14: Typical structural instance | E14: Tank-specific attachments, structural applicability and penetration ports | G14: 3 | H14: =IF(F14="",0,F14) -> 0
A15: FSTI | B15: FST I | C15: Yes | D15: Typical structural instance | E15: Tank-specific attachments, structural applicability and penetration ports | G15: 3 | H15: =IF(F15="",0,F15) -> 0
A16: FSTJ | B16: FST J | C16: Yes | D16: Typical structural instance | E16: Tank-specific attachments, structural applicability and penetration ports | G16: 6 | H16: =IF(F16="",0,F16) -> 0
... A27: WFT | B27: fire & service water structure (AW-FIRE) | C27: Yes | D27: Civil Guide Rev00 coordination reconstruction | E27: Revise and Resubmit; hydraulic/penstock/vendor/structural review comments remain open | G27: 7 | H27: =IF(F27="",0,F27) -> 0
A28: WPD | B28: WAS pre-dewatering building | C28: Yes | G28: 1 | H28: =IF(F28="",0,F28) -> 0
A29: BYPCH | B29: overflow bypass chamber (not modelled) | C29: No | D29: Not in master - tie-in position not checked | G29: 0 | H29: =IF(F29="",0,F29) -> 0
A30: CHUG25 | B30: chamber connecting UG-25 (not modelled) | C30: No | D30: Not in master - tie-in position not checked | G30: 0 | H30: =IF(F30="",0,F30) -> 0
A31: EXPST | B31: existing PST (not modelled) | C31: No | D31: Not in master - tie-in position not checked | G31: 0 | H31: =IF(F31="",0,F31) -> 0
A32: OUTF | B32: outfall chamber (not modelled) | C32: No | D32: Not in master - tie-in position not checked | G32: 0 | H32: =IF(F32="",0,F32) -> 0
A33: TEPS | B33: treated effluent pump station (not modelled) | C33: No | D33: Not in master - tie-in position not checked | G33: 0 | H33: =IF(F33="",0,F33) -> 0

Sheet Fronts
A1: Work fronts and crews
A2: Each front runs its run packages in the order on the Activities sheet (deeper lines first, downstream first). Crew numbers (yellow) divide the durations. Tie-in packages are outside the chains and assume a separate tie-in team when the structure is ready. Moving a line to another front needs a rebuild.
A4: Front | B4: Description | C4: Lines | D4: Packages | E4: Length (m) | F4: Piles (no.) | G4: Shored length (m) | H4: Piling rigs | I4: Sheet pile gangs | J4: Excavation gangs | K4: Slab gangs | L4: Pipe crews | M4: Backfill gangs | N4: Start | O4: Finish | P4: Duration (months)
A5: F1 | B5: Headworks & primary (GRT-PST-IPS) | C5: UG-01, UG-02, UG-03, UG-04 | D5: =COUNTIF(Packages!$C$6:$C$400,A5) -> 15 | E5: =SUMIF(Packages!$C$6:$C$400,A5,Packages!$O$6:$O$400) -> 800.35189 | F5: =SUMIF(Packages!$C$6:$C$400,A5,Packages!$AC$6:$AC$400) -> 569 | G5: =SUMIF(Packages!$C$6:$C$400,A5,Packages!$U$6:$U$400) -> 800.35189 | H5: 1 | I5: 1 | J5: 1 | K5: 1 | L5: 1 | M5: 1 | N5: =_xlfn.MINIFS(Packages!$AL$6:$AL$400,Packages!$C$6:$C$400,A5) -> 46357 | O5: =_xlfn.MAXIFS(Packages!$AM$6:$AM$400,Packages!$C$6:$C$400,A5) -> 46562 | P5: =(O5-N5)/30.4 -> 6.7434211
A6: F2 | B6: Bypass corridor: IPS bypass and outfall twin | C6: UG-05, UG-06, UG-24, UG-25, UG-26 | D6: =COUNTIF(Packages!$C$6:$C$400,A6) -> 14 | E6: =SUMIF(Packages!$C$6:$C$400,A6,Packages!$O$6:$O$400) -> 1724.1875 | F6: =SUMIF(Packages!$C$6:$C$400,A6,Packages!$AC$6:$AC$400) -> 1196 | G6: =SUMIF(Packages!$C$6:$C$400,A6,Packages!$U$6:$U$400) -> 1567.3564 | H6: 2 | I6: 2 | J6: 2 | K6: 2 | L6: 2 | M6: 2 | N6: =_xlfn.MINIFS(Packages!$AL$6:$AL$400,Packages!$C$6:$C$400,A6) -> 46357 | O6: =_xlfn.MAXIFS(Packages!$AM$6:$AM$400,Packages!$C$6:$C$400,A6) -> 46590 | P6: =(O6-N6)/30.4 -> 7.6644737
A7: F3 | B7: Distribution & FCT risers | C7: UG-08, UG-09, UG-10, UG-11B, UG-13A, UG-13B, UG-14E, UG-14F, UG-16B, UG-27J, UG-27K, UG-27L | D7: =COUNTIF(Packages!$C$6:$C$400,A7) -> 30 | E7: =SUMIF(Packages!$C$6:$C$400,A7,Packages!$O$6:$O$400) -> 1094.7783 | F7: =SUMIF(Packages!$C$6:$C$400,A7,Packages!$AC$6:$AC$400) -> 800 | G7: =SUMIF(Packages!$C$6:$C$400,A7,Packages!$U$6:$U$400) -> 648.70858 | H7: 1 | I7: 1 | J7: 1 | K7: 1 | L7: 1 | M7: 1 | N7: =_xlfn.MINIFS(Packages!$AL$6:$AL$400,Packages!$C$6:$C$400,A7) -> 46357 | O7: =_xlfn.MAXIFS(Packages!$AM$6:$AM$400,Packages!$C$6:$C$400,A7) -> 46594 | P7: =(O7-N7)/30.4 -> 7.7960526
A8: F4 | B8: FCT effluent A-H to CCT | C8: UG-07, UG-07A, UG-15, UG-15A | D8: =COUNTIF(Packages!$C$6:$C$400,A8) -> 22 | E8: =SUMIF(Packages!$C$6:$C$400,A8,Packages!$O$6:$O$400) -> 550.58554 | F8: =SUMIF(Packages!$C$6:$C$400,A8,Packages!$AC$6:$AC$400) -> 436 | G8: =SUMIF(Packages!$C$6:$C$400,A8,Packages!$U$6:$U$400) -> 308.43203 | H8: 1 | I8: 1 | J8: 1 | K8: 1 | L8: 1 | M8: 1 | N8: =_xlfn.MINIFS(Packages!$AL$6:$AL$400,Packages!$C$6:$C$400,A8) -> 46357 | O8: =_xlfn.MAXIFS(Packages!$AM$6:$AM$400,Packages!$C$6:$C$400,A8) -> 46621 | P8: =(O8-N8)/30.4 -> 8.6842105
A9: F5 | B9: FCT effluent I-L to CCT | C9: UG-07, UG-11, UG-11B, UG-12, UG-12A | D9: =COUNTIF(Packages!$C$6:$C$400,A9) -> 22 | E9: =SUMIF(Packages!$C$6:$C$400,A9,Packages!$O$6:$O$400) -> 570.56075 | F9: =SUMIF(Packages!$C$6:$C$400,A9,Packages!$AC$6:$AC$400) -> 452 | G9: =SUMIF(Packages!$C$6:$C$400,A9,Packages!$U$6:$U$400) -> 254.19719 | H9: 1 | I9: 1 | J9: 1 | K9: 1 | L9: 1 | M9: 1 | N9: =_xlfn.MINIFS(Packages!$AL$6:$AL$400,Packages!$C$6:$C$400,A9) -> 46357 | O9: =_xlfn.MAXIFS(Packages!$AM$6:$AM$400,Packages!$C$6:$C$400,A9) -> 46648 | P9: =(O9-N9)/30.4 -> 9.5723684
A10: F6 | B10: Sludge A-D,G,H to RAS/WAS + UG-23 | C10: UG-11, UG-11A, UG-11B, UG-14G, UG-14H, UG-16A, UG-16C, UG-16D, UG-23 | D10: =COUNTIF(Packages!$C$6:$C$400,A10) -> 34 | E10: =SUMIF(Packages!$C$6:$C$400,A10,Packages!$O$6:$O$400) -> 1164.3496 | F10: =SUMIF(Packages!$C$6:$C$400,A10,Packages!$AC$6:$AC$400) -> 765 | G10: =SUMIF(Packages!$C$6:$C$400,A10,Packages!$U$6:$U$400) -> 839.94228 | H10: 1 | I10: 1 | J10: 1 | K10: 1 | L10: 1 | M10: 1 | N10: =_xlfn.MINIFS(Packages!$AL$6:$AL$400,Packages!$C$6:$C$400,A10) -> 46357 | O10: =_xlfn.MAXIFS(Packages!$AM$6:$AM$400,Packages!$C$6:$C$400,A10) -> 46607 | P10: =(O10-N10)/30.4 -> 8.2236842
A11: F7 | B11: Sludge I-L,E,F to RAS/WAS | C11: UG-07A, UG-12, UG-13, UG-13A, UG-13B, UG-23, UG-27I | D11: =COUNTIF(Packages!$C$6:$C$400,A11) -> 38 | E11: =SUMIF(Packages!$C$6:$C$400,A11,Packages!$O$6:$O$400) -> 868.09874 | F11: =SUMIF(Packages!$C$6:$C$400,A11,Packages!$AC$6:$AC$400) -> 585 | G11: =SUMIF(Packages!$C$6:$C$400,A11,Packages!$U$6:$U$400) -> 816.15543 | H11: 1 | I11: 1 | J11: 1 | K11: 1 | L11: 1 | M11: 1 | N11: =_xlfn.MINIFS(Packages!$AL$6:$AL$400,Packages!$C$6:$C$400,A11) -> 46357 | O11: =_xlfn.MAXIFS(Packages!$AM$6:$AM$400,Packages!$C$6:$C$400,A11) -> 46606 | P11: =(O11-N11)/30.4 -> 8.1907895
A12: F8 | B12: Effluent, outfall & CCT links | C12: UG-11B, UG-15, UG-15A, UG-17, UG-18, UG-19, UG-20, UG-21, UG-22, UG-28, UG-28A | D12: =COUNTIF(Packages!$C$6:$C$400,A12) -> 26 | E12: =SUMIF(Packages!$C$6:$C$400,A12,Packages!$O$6:$O$400) -> 1378.4556 | F12: =SUMIF(Packages!$C$6:$C$400,A12,Packages!$AC$6:$AC$400) -> 985 | G12: =SUMIF(Packages!$C$6:$C$400,A12,Packages!$U$6:$U$400) -> 1326.4495 | H12: 2 | I12: 2 | J12: 2 | K12: 2 | L12: 2 | M12: 2 | N12: =_xlfn.MINIFS(Packages!$AL$6:$AL$400,Packages!$C$6:$C$400,A12) -> 46357 | O12: =_xlfn.MAXIFS(Packages!$AM$6:$AM$400,Packages!$C$6:$C$400,A12) -> 46572 | P12: =(O12-N12)/30.4 -> 7.0723684
A13: All | B13: All fronts | D13: =SUM(D5:D12) -> 201 | E13: =SUM(E5:E12) -> 8151.3679 | F13: =SUM(F5:F12) -> 5788 | G13: =SUM(G5:G12) -> 6561.5933 | H13: =SUM(H5:H12) -> 10 | I13: =SUM(I5:I12) -> 10 | J13: =SUM(J5:J12) -> 10 | K13: =SUM(K5:K12) -> 10 | ... M13: =SUM(M5:M12) -> 10 | N13: =MIN(N5:N12) -> 46357 | O13: =MAX(O5:O12) -> 46648 | P13: =(O13-N13)/30.4 -> 9.5723684
B14: Tie-in packages (separate team) | D14: =COUNTIF(Packages!$G$6:$G$400,"Tie-in")+COUNTIF(Packages!$G$6:$G$400,"Short connection") -> 71

Sheet Piece check
A1: Piece-level method check with groundwater at GWL
A2: One row per piece from the package workbook (10 m cuts). Open cut only where the dewatered open-cut reach fits short of the nearest other structure or pile AND the excavation is no deeper than MAXOC below GWL; otherwise sheet piles. Black = formula, blue = source data.
A5: Line | B5: Package | C5: Sub-piece | D5: Plan length (m) | E5: Planning OD (m) | F5: Start R (m) | G5: End R (m) | H5: Start crown (m) | I5: End crown (m) | J5: Nearest other structure / pile (m) | K5: R deepest (m) | L5: R average (m) | M5: Excavation depth from NG, avg (m) | N5: Depth below GWL, deepest (m) | O5: Depth NG to GWL used, deepest (m) | P5: Open-cut reach from axis (m) | Q5: Method | R5: Shored length (m) | S5: Depth below GWL, avg (m) | T5: Depth NG to GWL, avg (m) | U5: Trench bottom width (m) | V5: Excavation shored (m3) | W5: Excavation open cut (m3) | X5: Piled slab concrete (m3) | Y5: Pipe displacement below NG (m3) | Z5: Flotation FoS start, backfill to NG | AA5: Flotation FoS end, backfill to NG | AB5: Flotation FoS start, final to FL | AC5: Flotation FoS end, final to FL
A6: UG-01 | B6: UG-01-S01 | C6: P0022-01 | D6: 10 | E6: 2.5863866 | F6: -5.3931933 | G6: -5.4022798 | H6: -2.3068067 | I6: -2.3158932 | J6: 99 | K6: =MIN(F6,G6) -> -5.4022798 | L6: =AVERAGE(F6,G6) -> -5.3977365 | M6: =MAX(0,NG-L6) -> 4.6977365 | N6: =MAX(0,GWL-K6) -> 3.9022798 | O6: =MAX(0,NG-MAX(K6,GWL)) -> 0.8 | P6: =E6/2+WS+SLOPE_A*O6+SLOPE_B*N6 -> 11.297753 | Q6: =IF(AND(P6<J6,N6<=MAXOC),"Open cut","Shoring") -> Shoring | R6: =IF(Q6="Shoring",D6,0) -> 10 | S6: =MAX(0,GWL-L6) -> 3.8977365 | T6: =MAX(0,NG-MAX(L6,GWL)) -> 0.8 | U6: =E6+2*WS -> 4.5863866 | V6: =IF(Q6="Shoring",D6*M6*U6,0) -> 215.45636 | W6: =IF(Q6="Open cut",D6*(U6*M6+SLOPE_B*S6^2+2*SLOPE_B*S6*T6+SLOPE_A*T6^2),0) -> 0 | X6: =IF(M6>0,D6*(E6+2*SLABOVH)*SLAB,0) -> 17.931933 | Y6: =IF(M6>0,D6*PI()*E6^2/4,0) -> 52.538391 | Z6: =IF(H6-E6>=GWL,99,E6*(MAX(0,GWL-H6)*(GAM_S-GAM_W)+MAX(0,NG-MAX(H6,GWL))*GAM_D)/(GAM_W*PI()*E6^2/4)) -> 1.05421 | AA6: =IF(I6-E6>=GWL,99,E6*(MAX(0,GWL-I6)*(GAM_S-GAM_W)+MAX(0,NG-MAX(I6,GWL))*GAM_D)/(GAM_W*PI()*E6^2/4)) -> 1.0579445 | AB6: =IF(H6-E6>=GWL,99,E6*(MAX(0,GWL-H6)*(GAM_S-GAM_W)+MAX(0,FL-MAX(H6,GWL))*GAM_D)/(GAM_W*PI()*E6^2/4)) -> 2.5897782 | AC6: =IF(I6-E6>=GWL,99,E6*(MAX(0,GWL-I6)*(GAM_S-GAM_W)+MAX(0,FL-MAX(I6,GWL))*GAM_D)/(GAM_W*PI()*E6^2/4)) -> 2.5935126
A7: UG-01 | B7: UG-01-S01 | C7: P0022-02 | D7: 1.00536 | E7: 2.5863866 | F7: -5.4022798 | G7: -5.4031933 | H7: -2.3158932 | I7: -2.3168067 | J7: 99 | K7: =MIN(F7,G7) -> -5.4031933 | L7: =AVERAGE(F7,G7) -> -5.4027365 | M7: =MAX(0,NG-L7) -> 4.7027365 | N7: =MAX(0,GWL-K7) -> 3.9031933 | O7: =MAX(0,NG-MAX(K7,GWL)) -> 0.8 | P7: =E7/2+WS+SLOPE_A*O7+SLOPE_B*N7 -> 11.29958 | Q7: =IF(AND(P7<J7,N7<=MAXOC),"Open cut","Shoring") -> Shoring | R7: =IF(Q7="Shoring",D7,0) -> 1.00536 | S7: =MAX(0,GWL-L7) -> 3.9027365 | T7: =MAX(0,NG-MAX(L7,GWL)) -> 0.8 | U7: =E7+2*WS -> 4.5863866 | V7: =IF(Q7="Shoring",D7*M7*U7,0) -> 21.684175 | W7: =IF(Q7="Open cut",D7*(U7*M7+SLOPE_B*S7^2+2*SLOPE_B*S7*T7+SLOPE_A*T7^2),0) -> 0 | X7: =IF(M7>0,D7*(E7+2*SLABOVH)*SLAB,0) -> 1.8028048 | Y7: =IF(M7>0,D7*PI()*E7^2/4,0) -> 5.2819997 | Z7: =IF(H7-E7>=GWL,99,E7*(MAX(0,GWL-H7)*(GAM_S-GAM_W)+MAX(0,NG-MAX(H7,GWL))*GAM_D)/(GAM_W*PI()*E7^2/4)) -> 1.0579445 | AA7: =IF(I7-E7>=GWL,99,E7*(MAX(0,GWL-I7)*(GAM_S-GAM_W)+MAX(0,NG-MAX(I7,GWL))*GAM_D)/(GAM_W*PI()*E7^2/4)) -> 1.0583199 | AB7: =IF(H7-E7>=GWL,99,E7*(MAX(0,GWL-H7)*(GAM_S-GAM_W)+MAX(0,FL-MAX(H7,GWL))*GAM_D)/(GAM_W*PI()*E7^2/4)) -> 2.5935126 | AC7: =IF(I7-E7>=GWL,99,E7*(MAX(0,GWL-I7)*(GAM_S-GAM_W)+MAX(0,FL-MAX(I7,GWL))*GAM_D)/(GAM_W*PI()*E7^2/4)) -> 2.5938881
A8: UG-01 | B8: UG-01-S01 | C8: P0428 | D8: 3.900004 | E8: 2.5863866 | F8: -5.4031933 | G8: -5.4305033 | H8: -2.3168067 | I8: -2.3441167 | J8: 99 | K8: =MIN(F8,G8) -> -5.4305033 | L8: =AVERAGE(F8,G8) -> -5.4168483 | M8: =MAX(0,NG-L8) -> 4.7168483 | N8: =MAX(0,GWL-K8) -> 3.9305033 | O8: =MAX(0,NG-MAX(K8,GWL)) -> 0.8 | P8: =E8/2+WS+SLOPE_A*O8+SLOPE_B*N8 -> 11.3542 | Q8: =IF(AND(P8<J8,N8<=MAXOC),"Open cut","Shoring") -> Shoring | R8: =IF(Q8="Shoring",D8,0) -> 3.900004 | S8: =MAX(0,GWL-L8) -> 3.9168483 | T8: =MAX(0,NG-MAX(L8,GWL)) -> 0.8 | U8: =E8+2*WS -> 4.5863866 | V8: =IF(Q8="Shoring",D8*M8*U8,0) -> 84.369917 | W8: =IF(Q8="Open cut",D8*(U8*M8+SLOPE_B*S8^2+2*SLOPE_B*S8*T8+SLOPE_A*T8^2),0) -> 0 | X8: =IF(M8>0,D8*(E8+2*SLABOVH)*SLAB,0) -> 6.9934611 | Y8: =IF(M8>0,D8*PI()*E8^2/4,0) -> 20.489994 | Z8: =IF(H8-E8>=GWL,99,E8*(MAX(0,GWL-H8)*(GAM_S-GAM_W)+MAX(0,NG-MAX(H8,GWL))*GAM_D)/(GAM_W*PI()*E8^2/4)) -> 1.0583199 | AA8: =IF(I8-E8>=GWL,99,E8*(MAX(0,GWL-I8)*(GAM_S-GAM_W)+MAX(0,NG-MAX(I8,GWL))*GAM_D)/(GAM_W*PI()*E8^2/4)) -> 1.0695441 | AB8: =IF(H8-E8>=GWL,99,E8*(MAX(0,GWL-H8)*(GAM_S-GAM_W)+MAX(0,FL-MAX(H8,GWL))*GAM_D)/(GAM_W*PI()*E8^2/4)) -> 2.5938881 | AC8: =IF(I8-E8>=GWL,99,E8*(MAX(0,GWL-I8)*(GAM_S-GAM_W)+MAX(0,FL-MAX(I8,GWL))*GAM_D)/(GAM_W*PI()*E8^2/4)) -> 2.6051122
A9: UG-01 | B9: UG-01-S01 | C9: P0429 | D9: 3.8997991 | E9: 2.5559988 | F9: -5.4153094 | G9: -5.4426094 | H9: -2.3593106 | I9: -2.3866106 | J9: 99 | K9: =MIN(F9,G9) -> -5.4426094 | L9: =AVERAGE(F9,G9) -> -5.4289594 | M9: =MAX(0,NG-L9) -> 4.7289594 | N9: =MAX(0,GWL-K9) -> 3.9426094 | O9: =MAX(0,NG-MAX(K9,GWL)) -> 0.8 | P9: =E9/2+WS+SLOPE_A*O9+SLOPE_B*N9 -> 11.363218 | Q9: =IF(AND(P9<J9,N9<=MAXOC),"Open cut","Shoring") -> Shoring | R9: =IF(Q9="Shoring",D9,0) -> 3.8997991 | S9: =MAX(0,GWL-L9) -> 3.9289594 | T9: =MAX(0,NG-MAX(L9,GWL)) -> 0.8 | U9: =E9+2*WS -> 4.5559988 | V9: =IF(Q9="Shoring",D9*M9*U9,0) -> 84.021693 | W9: =IF(Q9="Open cut",D9*(U9*M9+SLOPE_B*S9^2+2*SLOPE_B*S9*T9+SLOPE_A*T9^2),0) -> 0 | X9: =IF(M9>0,D9*(E9+2*SLABOVH)*SLAB,0) -> 6.9338406 | Y9: =IF(M9>0,D9*PI()*E9^2/4,0) -> 20.010292 | Z9: =IF(H9-E9>=GWL,99,E9*(MAX(0,GWL-H9)*(GAM_S-GAM_W)+MAX(0,NG-MAX(H9,GWL))*GAM_D)/(GAM_W*PI()*E9^2/4)) -> 1.0885784 | AA9: =IF(I9-E9>=GWL,99,E9*(MAX(0,GWL-I9)*(GAM_S-GAM_W)+MAX(0,NG-MAX(I9,GWL))*GAM_D)/(GAM_W*PI()*E9^2/4)) -> 1.0999319 | AB9: =IF(H9-E9>=GWL,99,E9*(MAX(0,GWL-H9)*(GAM_S-GAM_W)+MAX(0,FL-MAX(H9,GWL))*GAM_D)/(GAM_W*PI()*E9^2/4)) -> 2.6424027 | AC9: =IF(I9-E9>=GWL,99,E9*(MAX(0,GWL-I9)*(GAM_S-GAM_W)+MAX(0,FL-MAX(I9,GWL))*GAM_D)/(GAM_W*PI()*E9^2/4)) -> 2.6537561
A10: UG-01 | B10: UG-01-S02 | C10: P0284-01 | D10: 1.1948369 | E10: 2.5559988 | F10: -5.4426094 | G10: -5.4509757 | H10: -2.3866106 | I10: -2.3949768 | J10: 12.83 | K10: =MIN(F10,G10) -> -5.4509757 | L10: =AVERAGE(F10,G10) -> -5.4467925 | M10: =MAX(0,NG-L10) -> 4.7467925 | N10: =MAX(0,GWL-K10) -> 3.9509757 | O10: =MAX(0,NG-MAX(K10,GWL)) -> 0.8 | P10: =E10/2+WS+SLOPE_A*O10+SLOPE_B*N10 -> 11.379951 | Q10: =IF(AND(P10<J10,N10<=MAXOC),"Open cut","Shoring") -> Shoring | R10: =IF(Q10="Shoring",D10,0) -> 1.1948369 | S10: =MAX(0,GWL-L10) -> 3.9467925 | T10: =MAX(0,NG-MAX(L10,GWL)) -> 0.8 | U10: =E10+2*WS -> 4.5559988 | V10: =IF(Q10="Shoring",D10*M10*U10,0) -> 25.839998 | W10: =IF(Q10="Open cut",D10*(U10*M10+SLOPE_B*S10^2+2*SLOPE_B*S10*T10+SLOPE_A*T10^2),0) -> 0 | X10: =IF(M10>0,D10*(E10+2*SLABOVH)*SLAB,0) -> 2.1244193 | Y10: =IF(M10>0,D10*PI()*E10^2/4,0) -> 6.1308376 | Z10: =IF(H10-E10>=GWL,99,E10*(MAX(0,GWL-H10)*(GAM_S-GAM_W)+MAX(0,NG-MAX(H10,GWL))*GAM_D)/(GAM_W*PI()*E10^2/4)) -> 1.0999319 | AA10: =IF(I10-E10>=GWL,99,E10*(MAX(0,GWL-I10)*(GAM_S-GAM_W)+MAX(0,NG-MAX(I10,GWL))*GAM_D)/(GAM_W*PI()*E10^2/4)) -> 1.1034112 | AB10: =IF(H10-E10>=GWL,99,E10*(MAX(0,GWL-H10)*(GAM_S-GAM_W)+MAX(0,FL-MAX(H10,GWL))*GAM_D)/(GAM_W*PI()*E10^2/4)) -> 2.6537561 | AC10: =IF(I10-E10>=GWL,99,E10*(MAX(0,GWL-I10)*(GAM_S-GAM_W)+MAX(0,FL-MAX(I10,GWL))*GAM_D)/(GAM_W*PI()*E10^2/4)) -> 2.6572354
A11: UG-01 | B11: UG-01-S02 | C11: P0284-02 | D11: 10 | E11: 2.5559988 | F11: -5.4509757 | G11: -5.5209957 | H11: -2.3949768 | I11: -2.4649968 | J11: 12.83 | K11: =MIN(F11,G11) -> -5.5209957 | L11: =AVERAGE(F11,G11) -> -5.4859857 | M11: =MAX(0,NG-L11) -> 4.7859857 | N11: =MAX(0,GWL-K11) -> 4.0209957 | O11: =MAX(0,NG-MAX(K11,GWL)) -> 0.8 | P11: =E11/2+WS+SLOPE_A*O11+SLOPE_B*N11 -> 11.519991 | Q11: =IF(AND(P11<J11,N11<=MAXOC),"Open cut","Shoring") -> Shoring | R11: =IF(Q11="Shoring",D11,0) -> 10 | S11: =MAX(0,GWL-L11) -> 3.9859857 | T11: =MAX(0,NG-MAX(L11,GWL)) -> 0.8 | U11: =E11+2*WS -> 4.5559988 | V11: =IF(Q11="Shoring",D11*M11*U11,0) -> 218.04945 | W11: =IF(Q11="Open cut",D11*(U11*M11+SLOPE_B*S11^2+2*SLOPE_B*S11*T11+SLOPE_A*T11^2),0) -> 0 | X11: =IF(M11>0,D11*(E11+2*SLABOVH)*SLAB,0) -> 17.779994 | Y11: =IF(M11>0,D11*PI()*E11^2/4,0) -> 51.311084 | Z11: =IF(H11-E11>=GWL,99,E11*(MAX(0,GWL-H11)*(GAM_S-GAM_W)+MAX(0,NG-MAX(H11,GWL))*GAM_D)/(GAM_W*PI()*E11^2/4)) -> 1.1034112 | AA11: =IF(I11-E11>=GWL,99,E11*(MAX(0,GWL-I11)*(GAM_S-GAM_W)+MAX(0,NG-MAX(I11,GWL))*GAM_D)/(GAM_W*PI()*E11^2/4)) -> 1.1325309 | AB11: =IF(H11-E11>=GWL,99,E11*(MAX(0,GWL-H11)*(GAM_S-GAM_W)+MAX(0,FL-MAX(H11,GWL))*GAM_D)/(GAM_W*PI()*E11^2/4)) -> 2.6572354 | AC11: =IF(I11-E11>=GWL,99,E11*(MAX(0,GWL-I11)*(GAM_S-GAM_W)+MAX(0,FL-MAX(I11,GWL))*GAM_D)/(GAM_W*PI()*E11^2/4)) -> 2.6863551
A12: UG-01 | B12: UG-01-S02 | C12: P0284-03 | D12: 10 | E12: 2.5559988 | F12: -5.5209957 | G12: -5.5910156 | H12: -2.4649968 | I12: -2.5350168 | J12: 12.84 | K12: =MIN(F12,G12) -> -5.5910156 | L12: =AVERAGE(F12,G12) -> -5.5560056 | M12: =MAX(0,NG-L12) -> 4.8560056 | N12: =MAX(0,GWL-K12) -> 4.0910156 | O12: =MAX(0,NG-MAX(K12,GWL)) -> 0.8 | P12: =E12/2+WS+SLOPE_A*O12+SLOPE_B*N12 -> 11.660031 | Q12: =IF(AND(P12<J12,N12<=MAXOC),"Open cut","Shoring") -> Shoring | R12: =IF(Q12="Shoring",D12,0) -> 10 | S12: =MAX(0,GWL-L12) -> 4.0560056 | T12: =MAX(0,NG-MAX(L12,GWL)) -> 0.8 | U12: =E12+2*WS -> 4.5559988 | V12: =IF(Q12="Shoring",D12*M12*U12,0) -> 221.23956 | W12: =IF(Q12="Open cut",D12*(U12*M12+SLOPE_B*S12^2+2*SLOPE_B*S12*T12+SLOPE_A*T12^2),0) -> 0 | X12: =IF(M12>0,D12*(E12+2*SLABOVH)*SLAB,0) -> 17.779994 | Y12: =IF(M12>0,D12*PI()*E12^2/4,0) -> 51.311084 | Z12: =IF(H12-E12>=GWL,99,E12*(MAX(0,GWL-H12)*(GAM_S-GAM_W)+MAX(0,NG-MAX(H12,GWL))*GAM_D)/(GAM_W*PI()*E12^2/4)) -> 1.1325309 | AA12: =IF(I12-E12>=GWL,99,E12*(MAX(0,GWL-I12)*(GAM_S-GAM_W)+MAX(0,NG-MAX(I12,GWL))*GAM_D)/(GAM_W*PI()*E12^2/4)) -> 1.1616505 | AB12: =IF(H12-E12>=GWL,99,E12*(MAX(0,GWL-H12)*(GAM_S-GAM_W)+MAX(0,FL-MAX(H12,GWL))*GAM_D)/(GAM_W*PI()*E12^2/4)) -> 2.6863551 | AC12: =IF(I12-E12>=GWL,99,E12*(MAX(0,GWL-I12)*(GAM_S-GAM_W)+MAX(0,FL-MAX(I12,GWL))*GAM_D)/(GAM_W*PI()*E12^2/4)) -> 2.7154747
A13: UG-01 | B13: UG-01-S02 | C13: P0284-04 | D13: 10 | E13: 2.5559988 | F13: -5.5910156 | G13: -5.6610356 | H13: -2.5350168 | I13: -2.6050368 | J13: 13.01 | K13: =MIN(F13,G13) -> -5.6610356 | L13: =AVERAGE(F13,G13) -> -5.6260256 | M13: =MAX(0,NG-L13) -> 4.9260256 | N13: =MAX(0,GWL-K13) -> 4.1610356 | O13: =MAX(0,NG-MAX(K13,GWL)) -> 0.8 | P13: =E13/2+WS+SLOPE_A*O13+SLOPE_B*N13 -> 11.800071 | Q13: =IF(AND(P13<J13,N13<=MAXOC),"Open cut","Shoring") -> Shoring | R13: =IF(Q13="Shoring",D13,0) -> 10 | S13: =MAX(0,GWL-L13) -> 4.1260256 | T13: =MAX(0,NG-MAX(L13,GWL)) -> 0.8 | U13: =E13+2*WS -> 4.5559988 | V13: =IF(Q13="Shoring",D13*M13*U13,0) -> 224.42967 | W13: =IF(Q13="Open cut",D13*(U13*M13+SLOPE_B*S13^2+2*SLOPE_B*S13*T13+SLOPE_A*T13^2),0) -> 0 | X13: =IF(M13>0,D13*(E13+2*SLABOVH)*SLAB,0) -> 17.779994 | Y13: =IF(M13>0,D13*PI()*E13^2/4,0) -> 51.311084 | Z13: =IF(H13-E13>=GWL,99,E13*(MAX(0,GWL-H13)*(GAM_S-GAM_W)+MAX(0,NG-MAX(H13,GWL))*GAM_D)/(GAM_W*PI()*E13^2/4)) -> 1.1616505 | AA13: =IF(I13-E13>=GWL,99,E13*(MAX(0,GWL-I13)*(GAM_S-GAM_W)+MAX(0,NG-MAX(I13,GWL))*GAM_D)/(GAM_W*PI()*E13^2/4)) -> 1.1907702 | AB13: =IF(H13-E13>=GWL,99,E13*(MAX(0,GWL-H13)*(GAM_S-GAM_W)+MAX(0,FL-MAX(H13,GWL))*GAM_D)/(GAM_W*PI()*E13^2/4)) -> 2.7154747 | AC13: =IF(I13-E13>=GWL,99,E13*(MAX(0,GWL-I13)*(GAM_S-GAM_W)+MAX(0,FL-MAX(I13,GWL))*GAM_D)/(GAM_W*PI()*E13^2/4)) -> 2.7445944
A14: UG-01 | B14: UG-01-S02 | C14: P0284-05 | D14: 10 | E14: 2.5559988 | F14: -5.6610356 | G14: -5.7310556 | H14: -2.6050368 | I14: -2.6750567 | J14: 17.64 | K14: =MIN(F14,G14) -> -5.7310556 | L14: =AVERAGE(F14,G14) -> -5.6960456 | M14: =MAX(0,NG-L14) -> 4.9960456 | N14: =MAX(0,GWL-K14) -> 4.2310556 | O14: =MAX(0,NG-MAX(K14,GWL)) -> 0.8 | P14: =E14/2+WS+SLOPE_A*O14+SLOPE_B*N14 -> 11.940111 | Q14: =IF(AND(P14<J14,N14<=MAXOC),"Open cut","Shoring") -> Shoring | R14: =IF(Q14="Shoring",D14,0) -> 10 | S14: =MAX(0,GWL-L14) -> 4.1960456 | T14: =MAX(0,NG-MAX(L14,GWL)) -> 0.8 | U14: =E14+2*WS -> 4.5559988 | V14: =IF(Q14="Shoring",D14*M14*U14,0) -> 227.61978 | W14: =IF(Q14="Open cut",D14*(U14*M14+SLOPE_B*S14^2+2*SLOPE_B*S14*T14+SLOPE_A*T14^2),0) -> 0 | X14: =IF(M14>0,D14*(E14+2*SLABOVH)*SLAB,0) -> 17.779994 | Y14: =IF(M14>0,D14*PI()*E14^2/4,0) -> 51.311084 | Z14: =IF(H14-E14>=GWL,99,E14*(MAX(0,GWL-H14)*(GAM_S-GAM_W)+MAX(0,NG-MAX(H14,GWL))*GAM_D)/(GAM_W*PI()*E14^2/4)) -> 1.1907702 | AA14: =IF(I14-E14>=GWL,99,E14*(MAX(0,GWL-I14)*(GAM_S-GAM_W)+MAX(0,NG-MAX(I14,GWL))*GAM_D)/(GAM_W*PI()*E14^2/4)) -> 1.2198899 | AB14: =IF(H14-E14>=GWL,99,E14*(MAX(0,GWL-H14)*(GAM_S-GAM_W)+MAX(0,FL-MAX(H14,GWL))*GAM_D)/(GAM_W*PI()*E14^2/4)) -> 2.7445944 | AC14: =IF(I14-E14>=GWL,99,E14*(MAX(0,GWL-I14)*(GAM_S-GAM_W)+MAX(0,FL-MAX(I14,GWL))*GAM_D)/(GAM_W*PI()*E14^2/4)) -> 2.7737141
A15: UG-01 | B15: UG-01-S02 | C15: P0284-06 | D15: 10 | E15: 2.5559988 | F15: -5.7310556 | G15: -5.8010756 | H15: -2.6750567 | I15: -2.7450767 | J15: 24.9 | K15: =MIN(F15,G15) -> -5.8010756 | L15: =AVERAGE(F15,G15) -> -5.7660656 | M15: =MAX(0,NG-L15) -> 5.0660656 | N15: =MAX(0,GWL-K15) -> 4.3010756 | O15: =MAX(0,NG-MAX(K15,GWL)) -> 0.8 | P15: =E15/2+WS+SLOPE_A*O15+SLOPE_B*N15 -> 12.080151 | Q15: =IF(AND(P15<J15,N15<=MAXOC),"Open cut","Shoring") -> Shoring | R15: =IF(Q15="Shoring",D15,0) -> 10 | S15: =MAX(0,GWL-L15) -> 4.2660656 | T15: =MAX(0,NG-MAX(L15,GWL)) -> 0.8 | U15: =E15+2*WS -> 4.5559988 | V15: =IF(Q15="Shoring",D15*M15*U15,0) -> 230.80989 | W15: =IF(Q15="Open cut",D15*(U15*M15+SLOPE_B*S15^2+2*SLOPE_B*S15*T15+SLOPE_A*T15^2),0) -> 0 | X15: =IF(M15>0,D15*(E15+2*SLABOVH)*SLAB,0) -> 17.779994 | Y15: =IF(M15>0,D15*PI()*E15^2/4,0) -> 51.311084 | Z15: =IF(H15-E15>=GWL,99,E15*(MAX(0,GWL-H15)*(GAM_S-GAM_W)+MAX(0,NG-MAX(H15,GWL))*GAM_D)/(GAM_W*PI()*E15^2/4)) -> 1.2198899 | AA15: =IF(I15-E15>=GWL,99,E15*(MAX(0,GWL-I15)*(GAM_S-GAM_W)+MAX(0,NG-MAX(I15,GWL))*GAM_D)/(GAM_W*PI()*E15^2/4)) -> 1.2490095 | AB15: =IF(H15-E15>=GWL,99,E15*(MAX(0,GWL-H15)*(GAM_S-GAM_W)+MAX(0,FL-MAX(H15,GWL))*GAM_D)/(GAM_W*PI()*E15^2/4)) -> 2.7737141 | AC15: =IF(I15-E15>=GWL,99,E15*(MAX(0,GWL-I15)*(GAM_S-GAM_W)+MAX(0,FL-MAX(I15,GWL))*GAM_D)/(GAM_W*PI()*E15^2/4)) -> 2.8028337
A16: UG-01 | B16: UG-01-S02 | C16: P0284-07 | D16: 10 | E16: 2.5559988 | F16: -5.8010756 | G16: -5.8710956 | H16: -2.7450767 | I16: -2.8150967 | J16: 99 | K16: =MIN(F16,G16) -> -5.8710956 | L16: =AVERAGE(F16,G16) -> -5.8360856 | M16: =MAX(0,NG-L16) -> 5.1360856 | N16: =MAX(0,GWL-K16) -> 4.3710956 | O16: =MAX(0,NG-MAX(K16,GWL)) -> 0.8 | P16: =E16/2+WS+SLOPE_A*O16+SLOPE_B*N16 -> 12.220191 | Q16: =IF(AND(P16<J16,N16<=MAXOC),"Open cut","Shoring") -> Shoring | R16: =IF(Q16="Shoring",D16,0) -> 10 | S16: =MAX(0,GWL-L16) -> 4.3360856 | T16: =MAX(0,NG-MAX(L16,GWL)) -> 0.8 | U16: =E16+2*WS -> 4.5559988 | V16: =IF(Q16="Shoring",D16*M16*U16,0) -> 234 | W16: =IF(Q16="Open cut",D16*(U16*M16+SLOPE_B*S16^2+2*SLOPE_B*S16*T16+SLOPE_A*T16^2),0) -> 0 | X16: =IF(M16>0,D16*(E16+2*SLABOVH)*SLAB,0) -> 17.779994 | Y16: =IF(M16>0,D16*PI()*E16^2/4,0) -> 51.311084 | Z16: =IF(H16-E16>=GWL,99,E16*(MAX(0,GWL-H16)*(GAM_S-GAM_W)+MAX(0,NG-MAX(H16,GWL))*GAM_D)/(GAM_W*PI()*E16^2/4)) -> 1.2490095 | AA16: =IF(I16-E16>=GWL,99,E16*(MAX(0,GWL-I16)*(GAM_S-GAM_W)+MAX(0,NG-MAX(I16,GWL))*GAM_D)/(GAM_W*PI()*E16^2/4)) -> 1.2781292 | AB16: =IF(H16-E16>=GWL,99,E16*(MAX(0,GWL-H16)*(GAM_S-GAM_W)+MAX(0,FL-MAX(H16,GWL))*GAM_D)/(GAM_W*PI()*E16^2/4)) -> 2.8028337 | AC16: =IF(I16-E16>=GWL,99,E16*(MAX(0,GWL-I16)*(GAM_S-GAM_W)+MAX(0,FL-MAX(I16,GWL))*GAM_D)/(GAM_W*PI()*E16^2/4)) -> 2.8319534
A17: UG-01 | B17: UG-01-S02 | C17: P0284-08 | D17: 10 | E17: 2.5559988 | F17: -5.8710956 | G17: -5.9411155 | H17: -2.8150967 | I17: -2.8851167 | J17: 99 | K17: =MIN(F17,G17) -> -5.9411155 | L17: =AVERAGE(F17,G17) -> -5.9061055 | M17: =MAX(0,NG-L17) -> 5.2061055 | N17: =MAX(0,GWL-K17) -> 4.4411155 | O17: =MAX(0,NG-MAX(K17,GWL)) -> 0.8 | P17: =E17/2+WS+SLOPE_A*O17+SLOPE_B*N17 -> 12.36023 | Q17: =IF(AND(P17<J17,N17<=MAXOC),"Open cut","Shoring") -> Shoring | R17: =IF(Q17="Shoring",D17,0) -> 10 | S17: =MAX(0,GWL-L17) -> 4.4061055 | T17: =MAX(0,NG-MAX(L17,GWL)) -> 0.8 | U17: =E17+2*WS -> 4.5559988 | V17: =IF(Q17="Shoring",D17*M17*U17,0) -> 237.19011 | W17: =IF(Q17="Open cut",D17*(U17*M17+SLOPE_B*S17^2+2*SLOPE_B*S17*T17+SLOPE_A*T17^2),0) -> 0 | X17: =IF(M17>0,D17*(E17+2*SLABOVH)*SLAB,0) -> 17.779994 | Y17: =IF(M17>0,D17*PI()*E17^2/4,0) -> 51.311084 | Z17: =IF(H17-E17>=GWL,99,E17*(MAX(0,GWL-H17)*(GAM_S-GAM_W)+MAX(0,NG-MAX(H17,GWL))*GAM_D)/(GAM_W*PI()*E17^2/4)) -> 1.2781292 | AA17: =IF(I17-E17>=GWL,99,E17*(MAX(0,GWL-I17)*(GAM_S-GAM_W)+MAX(0,NG-MAX(I17,GWL))*GAM_D)/(GAM_W*PI()*E17^2/4)) -> 1.3072488 | AB17: =IF(H17-E17>=GWL,99,E17*(MAX(0,GWL-H17)*(GAM_S-GAM_W)+MAX(0,FL-MAX(H17,GWL))*GAM_D)/(GAM_W*PI()*E17^2/4)) -> 2.8319534 | AC17: =IF(I17-E17>=GWL,99,E17*(MAX(0,GWL-I17)*(GAM_S-GAM_W)+MAX(0,FL-MAX(I17,GWL))*GAM_D)/(GAM_W*PI()*E17^2/4)) -> 2.8610731
... A1643: UG-28A | B1643: UG-28A-S01 | C1643: P0403 | D1643: 0.04551 | E1643: 0.31499353 | F1643: -0.53749677 | G1643: -0.53749677 | H1643: 0.27749677 | I1643: 0.27749677 | J1643: 16.11 | K1643: =MIN(F1643,G1643) -> -0.53749677 | L1643: =AVERAGE(F1643,G1643) -> -0.53749677 | M1643: =MAX(0,NG-L1643) -> 0 | N1643: =MAX(0,GWL-K1643) -> 0 | O1643: =MAX(0,NG-MAX(K1643,GWL)) -> 0 | P1643: =E1643/2+WS+SLOPE_A*O1643+SLOPE_B*N1643 -> 1.1574968 | Q1643: =IF(AND(P1643<J1643,N1643<=MAXOC),"Open cut","Shoring") -> Open cut | R1643: =IF(Q1643="Shoring",D1643,0) -> 0 | S1643: =MAX(0,GWL-L1643) -> 0 | T1643: =MAX(0,NG-MAX(L1643,GWL)) -> 0 | U1643: =E1643+2*WS -> 2.3149935 | V1643: =IF(Q1643="Shoring",D1643*M1643*U1643,0) -> 0 | W1643: =IF(Q1643="Open cut",D1643*(U1643*M1643+SLOPE_B*S1643^2+2*SLOPE_B*S1643*T1643+SLOPE_A*T1643^2),0) -> 0 | X1643: =IF(M1643>0,D1643*(E1643+2*SLABOVH)*SLAB,0) -> 0 | Y1643: =IF(M1643>0,D1643*PI()*E1643^2/4,0) -> 0 | Z1643: =IF(H1643-E1643>=GWL,99,E1643*(MAX(0,GWL-H1643)*(GAM_S-GAM_W)+MAX(0,NG-MAX(H1643,GWL))*GAM_D)/(GAM_W*PI()*E1643^2/4)) -> 99 | AA1643: =IF(I1643-E1643>=GWL,99,E1643*(MAX(0,GWL-I1643)*(GAM_S-GAM_W)+MAX(0,NG-MAX(I1643,GWL))*GAM_D)/(GAM_W*PI()*E1643^2/4)) -> 99 | AB1643: =IF(H1643-E1643>=GWL,99,E1643*(MAX(0,GWL-H1643)*(GAM_S-GAM_W)+MAX(0,FL-MAX(H1643,GWL))*GAM_D)/(GAM_W*PI()*E1643^2/4)) -> 99 | AC1643: =IF(I1643-E1643>=GWL,99,E1643*(MAX(0,GWL-I1643)*(GAM_S-GAM_W)+MAX(0,FL-MAX(I1643,GWL))*GAM_D)/(GAM_W*PI()*E1643^2/4)) -> 99

Sheet Packages
A1: Packages - method, quantities, dewatering, flotation and dates
A2: One row per work package from the package workbook (201). Method and quantities recalculate from Inputs and Piece check. Start / Finish come from the Activities sheet. Pile and sheet quantities are planning placeholders until designs exist.
A5: Line | B5: Package | C5: Front | D5: Planning name | E5: Pipe type | F5: Printed size | G5: Package type | H5: Tie-in structure(s) | I5: Structure ready (date) | J5: Aeration zones with open piles within 15 m | K5: Aeration gate (date) | L5: Crossing ID hold | M5: Fittings (no.) | N5: Planning OD (m) | O5: Plan length (m) | P5: R start (m) | Q5: R end (m) | R5: R deepest (m) | S5: Max depth below GWL (m) | T5: Max excavation depth from NG (m) | U5: Shored length (m) | V5: Open-cut length (m) | W5: Excavation method | X5: Excavation shored (m3) | Y5: Excavation open cut (m3) | Z5: Piled slab concrete (m3) | AA5: Pipe displacement (m3) | AB5: Backfill (m3) | AC5: Pipe-support piles (no.) | AD5: Sheet pile wall (m) | AE5: Sheet pile length (m) | AF5: Sheet pile area (m2) | AG5: Drawdown required below GWL (m) | AH5: Dewatering method | AI5: Min flotation FoS, backfill to NG | AJ5: Min flotation FoS, final to FL | AK5: Flotation action | AL5: Start | AM5: Finish | AN5: Sequence rank | AO5: Holds before release (package workbook) | AP5: Sequence notes (package workbook) | AQ5: Interactions used in the logic | AR5: Trench open after laying (days) | AS5: Dewatering running (days)
A6: UG-01 | B6: UG-01-S02 | C6: F1 | D6: GRP-UG01-S02-EL019-EL295-(-5.44/-6.52)-276m | E6: GRP | F6: 28 | G6: Run | I6: 0 | K6: 0 | L6: Yes | M6: 13 | N6: =_xlfn.MAXIFS('Piece check'!$E$6:$E$1643,'Piece check'!$B$6:$B$1643,B6) -> 2.5864043 | O6: =SUMIFS('Piece check'!$D$6:$D$1643,'Piece check'!$B$6:$B$1643,B6) -> 276.06057 | P6: -5.4426094 | Q6: -6.5165323 | R6: =_xlfn.MINIFS('Piece check'!$K$6:$K$1643,'Piece check'!$B$6:$B$1643,B6) -> -7.4373221 | S6: =MAX(0,GWL-R6) -> 5.9373221 | T6: =MAX(0,NG-R6) -> 6.7373221 | U6: =SUMIFS('Piece check'!$R$6:$R$1643,'Piece check'!$B$6:$B$1643,B6) -> 276.06057 | V6: =O6-U6 -> 0 | W6: =IF(U6<0.05,"Open cut",IF(V6<0.05,"Sheet piles","Mixed: "&TEXT(U6,"0")&" m sheet piles")) -> Sheet piles | X6: =SUMIFS('Piece check'!$V$6:$V$1643,'Piece check'!$B$6:$B$1643,B6) -> 7037.0478 | Y6: =SUMIFS('Piece check'!$W$6:$W$1643,'Piece check'!$B$6:$B$1643,B6) -> 0 | Z6: =SUMIFS('Piece check'!$X$6:$X$1643,'Piece check'!$B$6:$B$1643,B6) -> 488.87 | AA6: =SUMIFS('Piece check'!$Y$6:$Y$1643,'Piece check'!$B$6:$B$1643,B6) -> 1413.4105 | AB6: =MAX(0,X6+Y6-Z6-AA6) -> 5134.7674 | AC6: =(ROUNDUP(O6/PILE_SP,0)+1)*IF(N6>=PILE_THR,PILE_N_LARGE,PILE_N_SMALL) -> 188 | AD6: =2*U6 -> 552.12114 | AE6: =IF(U6>0,ROUNDUP(T6*SHEET_RATIO,0),0) -> 14 | AF6: =AD6*AE6 -> 7729.696 | AG6: =MAX(0,GWL-(R6-DD_BELOW)) -> 6.4373221 | AH6: =IF(AG6=0,"Not required",IF(AG6<=WP_LIMIT,"Single-stage wellpoints","Deep wells or two-stage wellpoints")) -> Deep wells or two-stage wellpoints | AI6: =MIN(_xlfn.MINIFS('Piece check'!$Z$6:$Z$1643,'Piece check'!$B$6:$B$1643,B6),_xlfn.MINIFS('Piece check'!$AA$6:$AA$1643,'Piece check'!$B$6:$B$1643,B6)) -> 1.0999319 | AJ6: =MIN(_xlfn.MINIFS('Piece check'!$AB$6:$AB$1643,'Piece check'!$B$6:$B$1643,B6),_xlfn.MINIFS('Piece check'!$AC$6:$AC$1643,'Piece check'!$B$6:$B$1643,B6)) -> 2.6537561 | AK6: =IF(AJ6<FOS_FLOT,"Anchor pipe to piled slab (permanent straps)",IF(AI6<FOS_FLOT,"Keep dewatering on until fill reaches FL, or strap to slab","No extra measure")) -> Keep dewatering on until fill reaches FL, or strap to slab | AL6: =Activities!P7 -> 46357 | AM6: =Activities!Q16 -> 46447 | AN6: 14 | AO6: Common holds only (see Read Me). | AP6: Identify P0279 (no level) before excavating. Where shoring is flagged, it is on the side facing the nearest structure or pile (Pieces, Nearest item). | AQ6: None | AR6: =Activities!P15-Activities!Q13 -> -15 | AS6: =IF(Activities!K10=0,0,Activities!Q16-Activities!P10) -> 65
A7: UG-01 | B7: UG-01-S03 | C7: F1 | D7: GRP-UG01-S03-EL295-PST-(-6.52/-6.52)-29m | E7: GRP | F7: 28 | G7: Tie-in | H7: PST | I7: =MAX(Structures!$H$21) -> 0 | K7: 0 | L7: No | M7: 0 | N7: =_xlfn.MAXIFS('Piece check'!$E$6:$E$1643,'Piece check'!$B$6:$B$1643,B7) -> 0.61306465 | O7: =SUMIFS('Piece check'!$D$6:$D$1643,'Piece check'!$B$6:$B$1643,B7) -> 29.41017 | P7: -6.5165323 | Q7: -6.5165323 | R7: =_xlfn.MINIFS('Piece check'!$K$6:$K$1643,'Piece check'!$B$6:$B$1643,B7) -> -6.5165323 | S7: =MAX(0,GWL-R7) -> 5.0165323 | T7: =MAX(0,NG-R7) -> 5.8165323 | U7: =SUMIFS('Piece check'!$R$6:$R$1643,'Piece check'!$B$6:$B$1643,B7) -> 29.41017 | V7: =O7-U7 -> 0 | W7: =IF(U7<0.05,"Open cut",IF(V7<0.05,"Sheet piles","Mixed: "&TEXT(U7,"0")&" m sheet piles")) -> Sheet piles | X7: =SUMIFS('Piece check'!$V$6:$V$1643,'Piece check'!$B$6:$B$1643,B7) -> 447.00444 | Y7: =SUMIFS('Piece check'!$W$6:$W$1643,'Piece check'!$B$6:$B$1643,B7) -> 0 | Z7: =SUMIFS('Piece check'!$X$6:$X$1643,'Piece check'!$B$6:$B$1643,B7) -> 23.720253 | AA7: =SUMIFS('Piece check'!$Y$6:$Y$1643,'Piece check'!$B$6:$B$1643,B7) -> 8.6816038 | AB7: =MAX(0,X7+Y7-Z7-AA7) -> 414.60258 | AC7: =(ROUNDUP(O7/PILE_SP,0)+1)*IF(N7>=PILE_THR,PILE_N_LARGE,PILE_N_SMALL) -> 11 | AD7: =2*U7 -> 58.82034 | AE7: =IF(U7>0,ROUNDUP(T7*SHEET_RATIO,0),0) -> 12 | AF7: =AD7*AE7 -> 705.84408 | AG7: =MAX(0,GWL-(R7-DD_BELOW)) -> 5.5165323 | AH7: =IF(AG7=0,"Not required",IF(AG7<=WP_LIMIT,"Single-stage wellpoints","Deep wells or two-stage wellpoints")) -> Deep wells or two-stage wellpoints | AI7: =MIN(_xlfn.MINIFS('Piece check'!$Z$6:$Z$1643,'Piece check'!$B$6:$B$1643,B7),_xlfn.MINIFS('Piece check'!$AA$6:$AA$1643,'Piece check'!$B$6:$B$1643,B7)) -> 9.8167181 | AJ7: =MIN(_xlfn.MINIFS('Piece check'!$AB$6:$AB$1643,'Piece check'!$B$6:$B$1643,B7),_xlfn.MINIFS('Piece check'!$AC$6:$AC$1643,'Piece check'!$B$6:$B$1643,B7)) -> 16.294947 | AK7: =IF(AJ7<FOS_FLOT,"Anchor pipe to piled slab (permanent straps)",IF(AI7<FOS_FLOT,"Keep dewatering on until fill reaches FL, or strap to slab","No extra measure")) -> No extra measure | AL7: =Activities!P18 -> 46359 | AM7: =Activities!Q27 -> 46451 | AN7: 15 | AO7: Common holds only (see Read Me). | AP7: PST wall and penetration built; its excavation backfilled to pipe zone. Lay as the closure to the structure. Where shoring is flagged, it is on the side facing the nearest structure or pile (Pieces, Nearest item). | AQ7: closure: lay after UG-01-S02 laid | AR7: =Activities!P26-Activities!Q24 -> -1 | AS7: =IF(Activities!K21=0,0,Activities!Q27-Activities!P21) -> 87
A8: UG-01 | B8: UG-01-S01 | C8: F1 | D8: GRP-UG01-S01-GRT-EL019-(-5.39/-5.44)-19m | E8: GRP | F8: 28 | G8: Tie-in | H8: GRT | I8: =MAX(Structures!$H$19) -> 0 | K8: 0 | L8: No | M8: 2 | N8: =_xlfn.MAXIFS('Piece check'!$E$6:$E$1643,'Piece check'!$B$6:$B$1643,B8) -> 2.5863866 | O8: =SUMIFS('Piece check'!$D$6:$D$1643,'Piece check'!$B$6:$B$1643,B8) -> 18.805163 | P8: -5.3931933 | Q8: -5.4426094 | R8: =_xlfn.MINIFS('Piece check'!$K$6:$K$1643,'Piece check'!$B$6:$B$1643,B8) -> -5.4426094 | S8: =MAX(0,GWL-R8) -> 3.9426094 | T8: =MAX(0,NG-R8) -> 4.7426094 | U8: =SUMIFS('Piece check'!$R$6:$R$1643,'Piece check'!$B$6:$B$1643,B8) -> 18.805163 | V8: =O8-U8 -> 0 | W8: =IF(U8<0.05,"Open cut",IF(V8<0.05,"Sheet piles","Mixed: "&TEXT(U8,"0")&" m sheet piles")) -> Sheet piles | X8: =SUMIFS('Piece check'!$V$6:$V$1643,'Piece check'!$B$6:$B$1643,B8) -> 405.53215 | Y8: =SUMIFS('Piece check'!$W$6:$W$1643,'Piece check'!$B$6:$B$1643,B8) -> 0 | Z8: =SUMIFS('Piece check'!$X$6:$X$1643,'Piece check'!$B$6:$B$1643,B8) -> 33.66204 | AA8: =SUMIFS('Piece check'!$Y$6:$Y$1643,'Piece check'!$B$6:$B$1643,B8) -> 98.320676 | AB8: =MAX(0,X8+Y8-Z8-AA8) -> 273.54943 | AC8: =(ROUNDUP(O8/PILE_SP,0)+1)*IF(N8>=PILE_THR,PILE_N_LARGE,PILE_N_SMALL) -> 16 | AD8: =2*U8 -> 37.610326 | AE8: =IF(U8>0,ROUNDUP(T8*SHEET_RATIO,0),0) -> 10 | AF8: =AD8*AE8 -> 376.10326 | AG8: =MAX(0,GWL-(R8-DD_BELOW)) -> 4.4426094 | AH8: =IF(AG8=0,"Not required",IF(AG8<=WP_LIMIT,"Single-stage wellpoints","Deep wells or two-stage wellpoints")) -> Single-stage wellpoints | AI8: =MIN(_xlfn.MINIFS('Piece check'!$Z$6:$Z$1643,'Piece check'!$B$6:$B$1643,B8),_xlfn.MINIFS('Piece check'!$AA$6:$AA$1643,'Piece check'!$B$6:$B$1643,B8)) -> 1.05421 | AJ8: =MIN(_xlfn.MINIFS('Piece check'!$AB$6:$AB$1643,'Piece check'!$B$6:$B$1643,B8),_xlfn.MINIFS('Piece check'!$AC$6:$AC$1643,'Piece check'!$B$6:$B$1643,B8)) -> 2.5897782 | AK8: =IF(AJ8<FOS_FLOT,"Anchor pipe to piled slab (permanent straps)",IF(AI8<FOS_FLOT,"Keep dewatering on until fill reaches FL, or strap to slab","No extra measure")) -> Keep dewatering on until fill reaches FL, or strap to slab | AL8: =Activities!P29 -> 46359 | AM8: =Activities!Q38 -> 46452 | AN8: 16 | AO8: Common holds only (see Read Me). | AP8: grit removal / fine screens wall and penetration built; its excavation backfilled to pipe zone. Lay as the closure to the structure. Where shoring is flagged, it is on the side facing the nearest structure or pile (Pieces, Nearest item). | AQ8: closure: lay after UG-01-S02 laid | AR8: =Activities!P37-Activities!Q35 -> -2 | AS8: =IF(Activities!K32=0,0,Activities!Q38-Activities!P32) -> 89
A9: UG-02 | B9: UG-02-S03 | C9: F1 | D9: GRP-UG02-S03-CH091-CH156-(-5.81/-6.17)-65m | E9: GRP | F9: 28 | G9: Run | I9: 0 | J9: 3, 5 (18 piles) | K9: =MAX(Aeration!$I$7,Aeration!$I$9) -> 46333 | L9: No | M9: 0 | N9: =_xlfn.MAXIFS('Piece check'!$E$6:$E$1643,'Piece check'!$B$6:$B$1643,B9) -> 2.0696095 | O9: =SUMIFS('Piece check'!$D$6:$D$1643,'Piece check'!$B$6:$B$1643,B9) -> 65.1 | P9: -5.8080994 | Q9: -6.167762 | R9: =_xlfn.MINIFS('Piece check'!$K$6:$K$1643,'Piece check'!$B$6:$B$1643,B9) -> -6.167762 | S9: =MAX(0,GWL-R9) -> 4.667762 | T9: =MAX(0,NG-R9) -> 5.467762 | U9: =SUMIFS('Piece check'!$R$6:$R$1643,'Piece check'!$B$6:$B$1643,B9) -> 65.1 | V9: =O9-U9 -> 0 | W9: =IF(U9<0.05,"Open cut",IF(V9<0.05,"Sheet piles","Mixed: "&TEXT(U9,"0")&" m sheet piles")) -> Sheet piles | X9: =SUMIFS('Piece check'!$V$6:$V$1643,'Piece check'!$B$6:$B$1643,B9) -> 1400.9398 | Y9: =SUMIFS('Piece check'!$W$6:$W$1643,'Piece check'!$B$6:$B$1643,B9) -> 0 | Z9: =SUMIFS('Piece check'!$X$6:$X$1643,'Piece check'!$B$6:$B$1643,B9) -> 99.915788 | AA9: =SUMIFS('Piece check'!$Y$6:$Y$1643,'Piece check'!$B$6:$B$1643,B9) -> 219.0018 | AB9: =MAX(0,X9+Y9-Z9-AA9) -> 1082.0222 | AC9: =(ROUNDUP(O9/PILE_SP,0)+1)*IF(N9>=PILE_THR,PILE_N_LARGE,PILE_N_SMALL) -> 46 | AD9: =2*U9 -> 130.2 | AE9: =IF(U9>0,ROUNDUP(T9*SHEET_RATIO,0),0) -> 11 | AF9: =AD9*AE9 -> 1432.2 | AG9: =MAX(0,GWL-(R9-DD_BELOW)) -> 5.167762 | AH9: =IF(AG9=0,"Not required",IF(AG9<=WP_LIMIT,"Single-stage wellpoints","Deep wells or two-stage wellpoints")) -> Deep wells or two-stage wellpoints | AI9: =MIN(_xlfn.MINIFS('Piece check'!$Z$6:$Z$1643,'Piece check'!$B$6:$B$1643,B9),_xlfn.MINIFS('Piece check'!$AA$6:$AA$1643,'Piece check'!$B$6:$B$1643,B9)) -> 1.7959693 | AJ9: =MIN(_xlfn.MINIFS('Piece check'!$AB$6:$AB$1643,'Piece check'!$B$6:$B$1643,B9),_xlfn.MINIFS('Piece check'!$AC$6:$AC$1643,'Piece check'!$B$6:$B$1643,B9)) -> 3.7149656 | AK9: =IF(AJ9<FOS_FLOT,"Anchor pipe to piled slab (permanent straps)",IF(AI9<FOS_FLOT,"Keep dewatering on until fill reaches FL, or strap to slab","No extra measure")) -> No extra measure | AL9: =Activities!P40 -> 46359 | AM9: =Activities!Q49 -> 46521 | AN9: 17 | AO9: No drawing level anchor inside the package: levels interpolated between anchors elsewhere (no longitudinal profile). | AP9: One shared excavation and dewatering front with UG-03: lay all pipes before backfill. Decide the sequence against the 18 pending piles within 15 m. Where shoring is flagged, it is on the side facing the nearest structure or pile (Pieces, Nearest item). | AQ9: shared trench with UG-03-S01: backfill after both laid; shared trench with UG-03-S02: backfill after both laid | AR9: =Activities!P48-Activities!Q46 -> 64 | AS9: =IF(Activities!K43=0,0,Activities!Q49-Activities!P43) -> 104
